Workbook

Sheet README
A1: ABSA x EXL - Agile Sprint Plan (in-depth)
A3: Anchoring: Sprint 1 = Mon 2026-06-15. 12 sprints x 2 weeks ~ 6 months.
A4: Group 1 ABSA sign-off targeted end of Sprint 8 (2026-10-02). All 10 models live by end S11; Group 2 sign-off + go-live end S12.
A6: TEAM SHAPE - 8 people (right-sized for a solid 12 sprints):
A7: - 2 AWS/MLOps engineers split the foundation: AWS (Foundation & Infra) + AWS2 (Platform, Compute &
A8: MLOps). The total AWS workload is only ~62 effort-days, so 2 carry it at a healthy ~75% peak;
A9: a 3rd was dropped as under-utilized (it sat idle most of S8-S12).
A10: - 3 SAS developers: two from S1 run Group 1 models 1 & 2 IN PARALLEL (kills bus-factor-of-one on
A11: the proof); a third onboards S8 for Group 2.
A12: Group 2 (8 models) is compressed into S9-S11 (3 models/sprint, then 2) so ALL 10 are live by end S11,
A13: leaving S12 entirely for hardening, sign-off, and handover - not a race to finish models.
A14: The S5 capacity review (T-1301) confirms the 3rd SAS dev + plans AWS ramp-down after foundation.
... A48: migration, onboarding 10 SAS models, security/compliance hardening, testing/UAT, and go-live.

Sheet Backlog
A1: Backlog - EPIC / Story / Task
A3: Type | B3: ID | C3: Parent | D3: Epic | E3: Title | F3: Role | G3: Sprint | H3: Est (d) | I3: Pts | J3: MoSCoW | K3: Depends On | L3: Blocked On (ABSA) | M3: Status | N3: Acceptance / Notes
A4: EPIC | B4: E01 | D4: E01 | E4: Team Onboarding & Governance - Everyone productive in week 1: repo green locally, board live, ABSA dependency register running. | F4: TL | G4: S1
A5: Story | B5: ST-0101 | C5: E01 | D5: E01 | E5: Environment & platform onboarding | G5: S1 | H5: 7 | I5: 8 | J5: Must | N5: All engineers: 278-test suite green + `make demo` exit 0 locally; walkthrough attended.
A6: Task | B6: T-0101 | C6: ST-0101 | D6: E01 | E6: Clone repo, uv sync, run full 278-test suite locally | F6: AWS | G6: S1 | H6: 0.5 | M6: Planned
A7: Task | B7: T-0102 | C7: ST-0101 | D7: E01 | E7: Clone repo, uv sync, run full 278-test suite locally | F7: DE | G7: S1 | H7: 0.5 | M7: Planned
A8: Task | B8: T-0103 | C8: ST-0101 | D8: E01 | E8: Clone repo, uv sync, run full 278-test suite locally | F8: SAS | G8: S1 | H8: 0.5 | M8: Planned
A9: Task | B9: T-0104 | C9: ST-0101 | D9: E01 | E9: Clone repo, uv sync, run full 278-test suite locally | F9: DevOps | G9: S1 | H9: 0.5 | M9: Planned
A10: Task | B10: T-0105 | C10: ST-0101 | D10: E01 | E10: Run `make demo` (LocalStack chain) green locally | F10: AWS | G10: S1 | H10: 0.5 | K10: T-0101 | M10: Planned
A11: Task | B11: T-0106 | C11: ST-0101 | D11: E01 | E11: Run `make demo` (LocalStack chain) green locally | F11: DE | G11: S1 | H11: 0.5 | K11: T-0102 | M11: Planned
A12: Task | B12: T-0107 | C12: ST-0101 | D12: E01 | E12: Run `make demo` (LocalStack chain) green locally | F12: SAS | G12: S1 | H12: 0.5 | K12: T-0103 | M12: Planned
A13: Task | B13: T-0108 | C13: ST-0101 | D13: E01 | E13: Run `make demo` (LocalStack chain) green locally | F13: DevOps | G13: S1 | H13: 0.5 | K13: T-0104 | M13: Planned
A14: Task | B14: T-0101b | C14: ST-0101 | D14: E01 | E14: Clone repo, uv sync, tests green locally | F14: AWS2 | G14: S1 | H14: 0.5 | M14: Planned
A15: Task | B15: T-0103b | C15: ST-0101 | D15: E01 | E15: Clone repo, uv sync, tests green locally | F15: SAS2 | G15: S1 | H15: 0.5 | M15: Planned
A16: Task | B16: T-0105b | C16: ST-0101 | D16: E01 | E16: Run `make demo` green locally | F16: AWS2 | G16: S1 | H16: 0.5 | K16: T-0101b | M16: Planned
A17: Task | B17: T-0107b | C17: ST-0101 | D17: E01 | E17: Run `make demo` green locally | F17: SAS2 | G17: S1 | H17: 0.5 | K17: T-0103b | M17: Planned
A18: Task | B18: T-0109 | C18: ST-0101 | D18: E01 | E18: Host architecture walkthrough: chain-of-custody, repo tour, ADR index | F18: TL | G18: S1 | H18: 1 | M18: Planned | N18: Record for future joiners
A19: Story | B19: ST-0102 | C19: E01 | D19: E01 | E19: Agile working agreement & board | G19: S1 | H19: 2 | I19: 2 | J19: Must | N19: Jira board mirrors this backlog; DoR/DoD + ceremony calendar published.
A20: Task | B20: T-0110 | C20: ST-0102 | D20: E01 | E20: Stand up Jira/ADO board; import this EPIC/Story/Task tree | F20: TL | G20: S1 | H20: 1 | M20: Planned | N20: Backlog sheet is the import source
A21: Task | B21: T-0111 | C21: ST-0102 | D21: E01 | E21: Publish Definition of Ready/Done + PR / branch-protection workflow | F21: TL | G21: S1 | H21: 0.5 | M21: Planned
A22: Task | B22: T-0112 | C22: ST-0102 | D22: E01 | E22: Ceremony calendar: standup, planning, review+demo, retro | F22: TL | G22: S1 | H22: 0.5 | M22: Planned
A23: Story | B23: ST-0103 | C23: E01 | D23: E01 | E23: ABSA dependency management | G23: S1 | H23: 1 | I23: 1 | J23: Must | N23: 8-item ask-list sent; weekly chase cadence running with named SPOC.
A24: Task | B24: T-0113 | C24: ST-0103 | D24: E01 | E24: Send 8-item dependency ask-list to ABSA SPOC | F24: TL | G24: S1 | H24: 0.5 | M24: Planned | N24: Accounts, IAM, SAS runtime, PIR, data movement, CAB/IVU, network, model docs
A25: Task | B25: T-0114 | C25: ST-0103 | D25: E01 | E25: Stand up weekly dependency-chase cadence + escalation path | F25: TL | G25: S1 | H25: 0.5 | K25: T-0113 | M25: Planned
A26: EPIC | B26: E02 | D26: E02 | E26: CI/CD on Existing Jenkins - Migrate all 6 CI gates from GitHub Actions to the standalone Jenkins per ADR-0011; retire GHA. | F26: DevOps | G26: S1-S3
A27: Story | B27: ST-0201 | C27: E02 | D27: E02 | E27: Jenkins discovery & identity decision | G27: S1 | H27: 2.5 | I27: 3 | J27: Must | N27: Topology documented; auth path chosen; ADR-0011 amended.
A28: Task | B28: T-0201 | C28: ST-0201 | D28: E02 | E28: Document Jenkins topology: host, agents, executors, plugins, versions | F28: DevOps | G28: S1 | H28: 1 | M28: Planned | N28: Standalone instance already running
A29: Task | B29: T-0202 | C29: ST-0201 | D29: E02 | E29: Choose AWS auth path: instance profile / OIDC IdP plugin / keys+rotation | F29: DevOps | G29: S1 | H29: 1 | K29: T-0201 | M29: Planned | N29: Drives signing-foundation trust policy
A30: Task | B30: T-0203 | C30: ST-0201 | D30: E02 | E30: Amend ADR-0011 with the standalone-Jenkins identity decision | F30: TL | G30: S1 | H30: 0.5 | K30: T-0202 | M30: Planned
A31: Story | B31: ST-0202 | C31: E02 | D31: E02 | E31: Shared library proving ground | G31: S1-S2 | H31: 4.5 | I31: 5 | J31: Must | N31: absa-ci registered; ci/python-validate status visible on a GitHub PR.
A32: Task | B32: T-0204 | C32: ST-0202 | D32: E02 | E32: Register absa-ci as Global Pipeline Library | F32: DevOps | G32: S1 | H32: 0.5 | K32: T-0201 | M32: Planned | N32: ci/jenkins/ path in this repo
A33: Task | B33: T-0205 | C33: ST-0202 | D33: E02 | E33: Create multibranch job for python-validate; first run | F33: DevOps | G33: S1 | H33: 1 | K33: T-0204 | M33: Planned
A34: Task | B34: T-0206 | C34: ST-0202 | D34: E02 | E34: Verify ci/python-validate commit status lands on a GitHub PR | F34: DevOps | G34: S1 | H34: 1 | K34: T-0205 | M34: Planned | N34: Branch-protection sandbox check
A35: Task | B35: T-0207 | C35: ST-0202 | D35: E02 | E35: Fix shared-library Groovy issues surfaced by first runs | F35: DevOps | G35: S2 | H35: 2 | K35: T-0206 | M35: Planned | N35: publishChecks plugin quirks, PATH handling
A36: Story | B36: ST-0203 | C36: E02 | D36: E02 | E36: No-AWS pipelines live | G36: S2 | H36: 5 | I36: 5 | J36: Must | N36: code-intake, terraform-validate, localstack-demo jobs green on Jenkins.
A37: Task | B37: T-0208 | C37: ST-0203 | D37: E02 | E37: code-intake job live | F37: DevOps | G37: S2 | H37: 0.5 | K37: T-0207 | M37: Planned
A38: Task | B38: T-0209 | C38: ST-0203 | D38: E02 | E38: terraform-validate job live (docker tflint/tfsec/checkov/gitleaks) | F38: DevOps | G38: S2 | H38: 1.5 | K38: T-0207 | M38: Planned
A39: Task | B39: T-0210 | C39: ST-0203 | D39: E02 | E39: localstack-demo job live (Docker on agent, 0/1/2/3 exit-code gate) | F39: DevOps | G39: S2 | H39: 2 | K39: T-0207 | M39: Planned | N39: Needs Docker socket on agent
A40: Task | B40: T-0211 | C40: ST-0203 | D40: E02 | E40: Wire platform secrets into Jenkins credentials store | F40: DevOps | G40: S2 | H40: 1 | K40: T-0202 | M40: Planned | N40: Secrets Manager-backed if reachable
A41: Story | B41: ST-0204 | C41: E02 | D41: E02 | E41: AWS-touching pipelines + cutover | G41: S3 | H41: 6.5 | I41: 8 | J41: Must | N41: sign/register green vs real AWS; 1-week parallel run byte-identical; branch protection flipped; GHA disabled.
...

Sheet Sprint Plan
A1: Sprint Plan - 12 x 2-week sprints
A3: Sprint | B3: Start | C3: End | D3: Goal | E3: Milestone | F3: AWS (d) | G3: AWS2 (d) | H3: DE (d) | I3: SAS (d) | J3: SAS2 (d) | K3: SAS3 (d) | L3: DevOps (d) | M3: TL (d) | N3: Total (d)
A4: S1 | B4: 46188 | C4: 46199 | D4: Team onboarded; Jenkins identity decided; python-validate green on Jenkins; ABSA ask-list sent | F4: =SUMIFS(Backlog!$H:$H,Backlog!$F:$F,"AWS",Backlog!$G:$G,"S1",Backlog!$A:$A,"Task") | G4: =SUMIFS(Backlog!$H:$H,Backlog!$F:$F,"AWS2",Backlog!$G:$G,"S1",Backlog!$A:$A,"Task") | H4: =SUMIFS(Backlog!$H:$H,Backlog!$F:$F,"DE",Backlog!$G:$G,"S1",Backlog!$A:$A,"Task") | I4: =SUMIFS(Backlog!$H:$H,Backlog!$F:$F,"SAS",Backlog!$G:$G,"S1",Backlog!$A:$A,"Task") | J4: =SUMIFS(Backlog!$H:$H,Backlog!$F:$F,"SAS2",Backlog!$G:$G,"S1",Backlog!$A:$A,"Task") | K4: =SUMIFS(Backlog!$H:$H,Backlog!$F:$F,"SAS3",Backlog!$G:$G,"S1",Backlog!$A:$A,"Task") | L4: =SUMIFS(Backlog!$H:$H,Backlog!$F:$F,"DevOps",Backlog!$G:$G,"S1",Backlog!$A:$A,"Task") | M4: =SUMIFS(Backlog!$H:$H,Backlog!$F:$F,"TL",Backlog!$G:$G,"S1",Backlog!$A:$A,"Task") | N4: =SUM(F4:M4)
A5: S2 | B5: 46202 | C5: 46213 | D5: All no-AWS Jenkins jobs live; AWS bootstrap applied; data contracts started; SAS model-1 review done | F5: =SUMIFS(Backlog!$H:$H,Backlog!$F:$F,"AWS",Backlog!$G:$G,"S2",Backlog!$A:$A,"Task") | G5: =SUMIFS(Backlog!$H:$H,Backlog!$F:$F,"AWS2",Backlog!$G:$G,"S2",Backlog!$A:$A,"Task") | H5: =SUMIFS(Backlog!$H:$H,Backlog!$F:$F,"DE",Backlog!$G:$G,"S2",Backlog!$A:$A,"Task") | I5: =SUMIFS(Backlog!$H:$H,Backlog!$F:$F,"SAS",Backlog!$G:$G,"S2",Backlog!$A:$A,"Task") | J5: =SUMIFS(Backlog!$H:$H,Backlog!$F:$F,"SAS2",Backlog!$G:$G,"S2",Backlog!$A:$A,"Task") | K5: =SUMIFS(Backlog!$H:$H,Backlog!$F:$F,"SAS3",Backlog!$G:$G,"S2",Backlog!$A:$A,"Task") | L5: =SUMIFS(Backlog!$H:$H,Backlog!$F:$F,"DevOps",Backlog!$G:$G,"S2",Backlog!$A:$A,"Task") | M5: =SUMIFS(Backlog!$H:$H,Backlog!$F:$F,"TL",Backlog!$G:$G,"S2",Backlog!$A:$A,"Task") | N5: =SUM(F5:M5)
A6: S3 | B6: 46216 | C6: 46227 | D6: Jenkins cutover complete (GHA retired); signing foundation live on real AWS; model-1 optimized | E6: Jenkins is the sole CI gate | F6: =SUMIFS(Backlog!$H:$H,Backlog!$F:$F,"AWS",Backlog!$G:$G,"S3",Backlog!$A:$A,"Task") | G6: =SUMIFS(Backlog!$H:$H,Backlog!$F:$F,"AWS2",Backlog!$G:$G,"S3",Backlog!$A:$A,"Task") | H6: =SUMIFS(Backlog!$H:$H,Backlog!$F:$F,"DE",Backlog!$G:$G,"S3",Backlog!$A:$A,"Task") | I6: =SUMIFS(Backlog!$H:$H,Backlog!$F:$F,"SAS",Backlog!$G:$G,"S3",Backlog!$A:$A,"Task") | J6: =SUMIFS(Backlog!$H:$H,Backlog!$F:$F,"SAS2",Backlog!$G:$G,"S3",Backlog!$A:$A,"Task") | K6: =SUMIFS(Backlog!$H:$H,Backlog!$F:$F,"SAS3",Backlog!$G:$G,"S3",Backlog!$A:$A,"Task") | L6: =SUMIFS(Backlog!$H:$H,Backlog!$F:$F,"DevOps",Backlog!$G:$G,"S3",Backlog!$A:$A,"Task") | M6: =SUMIFS(Backlog!$H:$H,Backlog!$F:$F,"TL",Backlog!$G:$G,"S3",Backlog!$A:$A,"Task") | N6: =SUM(F6:M6)
A7: S4 | B7: 46230 | C7: 46241 | D7: Registry API live on Lambda (dev); replication path validated; model-1 packaged; threat model done | E7: Registry live in dev | F7: =SUMIFS(Backlog!$H:$H,Backlog!$F:$F,"AWS",Backlog!$G:$G,"S4",Backlog!$A:$A,"Task") | G7: =SUMIFS(Backlog!$H:$H,Backlog!$F:$F,"AWS2",Backlog!$G:$G,"S4",Backlog!$A:$A,"Task") | H7: =SUMIFS(Backlog!$H:$H,Backlog!$F:$F,"DE",Backlog!$G:$G,"S4",Backlog!$A:$A,"Task") | I7: =SUMIFS(Backlog!$H:$H,Backlog!$F:$F,"SAS",Backlog!$G:$G,"S4",Backlog!$A:$A,"Task") | J7: =SUMIFS(Backlog!$H:$H,Backlog!$F:$F,"SAS2",Backlog!$G:$G,"S4",Backlog!$A:$A,"Task") | K7: =SUMIFS(Backlog!$H:$H,Backlog!$F:$F,"SAS3",Backlog!$G:$G,"S4",Backlog!$A:$A,"Task") | L7: =SUMIFS(Backlog!$H:$H,Backlog!$F:$F,"DevOps",Backlog!$G:$G,"S4",Backlog!$A:$A,"Task") | M7: =SUMIFS(Backlog!$H:$H,Backlog!$F:$F,"TL",Backlog!$G:$G,"S4",Backlog!$A:$A,"Task") | N7: =SUM(F7:M7)
A8: S5 | B8: 46244 | C8: 46255 | D8: SFN executes model-1 in dev; PIR sync; model-2 optimized; CAPACITY REVIEW (scale-up decision) | E8: *** S5 CAPACITY REVIEW *** | F8: =SUMIFS(Backlog!$H:$H,Backlog!$F:$F,"AWS",Backlog!$G:$G,"S5",Backlog!$A:$A,"Task") | G8: =SUMIFS(Backlog!$H:$H,Backlog!$F:$F,"AWS2",Backlog!$G:$G,"S5",Backlog!$A:$A,"Task") | H8: =SUMIFS(Backlog!$H:$H,Backlog!$F:$F,"DE",Backlog!$G:$G,"S5",Backlog!$A:$A,"Task") | I8: =SUMIFS(Backlog!$H:$H,Backlog!$F:$F,"SAS",Backlog!$G:$G,"S5",Backlog!$A:$A,"Task") | J8: =SUMIFS(Backlog!$H:$H,Backlog!$F:$F,"SAS2",Backlog!$G:$G,"S5",Backlog!$A:$A,"Task") | K8: =SUMIFS(Backlog!$H:$H,Backlog!$F:$F,"SAS3",Backlog!$G:$G,"S5",Backlog!$A:$A,"Task") | L8: =SUMIFS(Backlog!$H:$H,Backlog!$F:$F,"DevOps",Backlog!$G:$G,"S5",Backlog!$A:$A,"Task") | M8: =SUMIFS(Backlog!$H:$H,Backlog!$F:$F,"TL",Backlog!$G:$G,"S5",Backlog!$A:$A,"Task") | N8: =SUM(F8:M8)
A9: S6 | B9: 46258 | C9: 46269 | D9: DRESS REHEARSAL: full chain on real AWS for models 1-2; dashboards + perf harness; POPIA/SARB check | E9: Dress rehearsal pass | F9: =SUMIFS(Backlog!$H:$H,Backlog!$F:$F,"AWS",Backlog!$G:$G,"S6",Backlog!$A:$A,"Task") | G9: =SUMIFS(Backlog!$H:$H,Backlog!$F:$F,"AWS2",Backlog!$G:$G,"S6",Backlog!$A:$A,"Task") | H9: =SUMIFS(Backlog!$H:$H,Backlog!$F:$F,"DE",Backlog!$G:$G,"S6",Backlog!$A:$A,"Task") | I9: =SUMIFS(Backlog!$H:$H,Backlog!$F:$F,"SAS",Backlog!$G:$G,"S6",Backlog!$A:$A,"Task") | J9: =SUMIFS(Backlog!$H:$H,Backlog!$F:$F,"SAS2",Backlog!$G:$G,"S6",Backlog!$A:$A,"Task") | K9: =SUMIFS(Backlog!$H:$H,Backlog!$F:$F,"SAS3",Backlog!$G:$G,"S6",Backlog!$A:$A,"Task") | L9: =SUMIFS(Backlog!$H:$H,Backlog!$F:$F,"DevOps",Backlog!$G:$G,"S6",Backlog!$A:$A,"Task") | M9: =SUMIFS(Backlog!$H:$H,Backlog!$F:$F,"TL",Backlog!$G:$G,"S6",Backlog!$A:$A,"Task") | N9: =SUM(F9:M9)
A10: S7 | B10: 46272 | C10: 46283 | D10: Group 1 initial production scoring; reconciliation; perf + resilience tests; UAT plan | F10: =SUMIFS(Backlog!$H:$H,Backlog!$F:$F,"AWS",Backlog!$G:$G,"S7",Backlog!$A:$A,"Task") | G10: =SUMIFS(Backlog!$H:$H,Backlog!$F:$F,"AWS2",Backlog!$G:$G,"S7",Backlog!$A:$A,"Task") | H10: =SUMIFS(Backlog!$H:$H,Backlog!$F:$F,"DE",Backlog!$G:$G,"S7",Backlog!$A:$A,"Task") | I10: =SUMIFS(Backlog!$H:$H,Backlog!$F:$F,"SAS",Backlog!$G:$G,"S7",Backlog!$A:$A,"Task") | J10: =SUMIFS(Backlog!$H:$H,Backlog!$F:$F,"SAS2",Backlog!$G:$G,"S7",Backlog!$A:$A,"Task") | K10: =SUMIFS(Backlog!$H:$H,Backlog!$F:$F,"SAS3",Backlog!$G:$G,"S7",Backlog!$A:$A,"Task") | L10: =SUMIFS(Backlog!$H:$H,Backlog!$F:$F,"DevOps",Backlog!$G:$G,"S7",Backlog!$A:$A,"Task") | M10: =SUMIFS(Backlog!$H:$H,Backlog!$F:$F,"TL",Backlog!$G:$G,"S7",Backlog!$A:$A,"Task") | N10: =SUM(F10:M10)
A11: S8 | B11: 46286 | C11: 46297 | D11: GROUP 1 ABSA SIGN-OFF; pen-test remediation; 2nd SAS dev onboarded; G2 plan | E11: *** GROUP 1 SIGN-OFF *** | F11: =SUMIFS(Backlog!$H:$H,Backlog!$F:$F,"AWS",Backlog!$G:$G,"S8",Backlog!$A:$A,"Task") | G11: =SUMIFS(Backlog!$H:$H,Backlog!$F:$F,"AWS2",Backlog!$G:$G,"S8",Backlog!$A:$A,"Task") | H11: =SUMIFS(Backlog!$H:$H,Backlog!$F:$F,"DE",Backlog!$G:$G,"S8",Backlog!$A:$A,"Task") | I11: =SUMIFS(Backlog!$H:$H,Backlog!$F:$F,"SAS",Backlog!$G:$G,"S8",Backlog!$A:$A,"Task") | J11: =SUMIFS(Backlog!$H:$H,Backlog!$F:$F,"SAS2",Backlog!$G:$G,"S8",Backlog!$A:$A,"Task") | K11: =SUMIFS(Backlog!$H:$H,Backlog!$F:$F,"SAS3",Backlog!$G:$G,"S8",Backlog!$A:$A,"Task") | L11: =SUMIFS(Backlog!$H:$H,Backlog!$F:$F,"DevOps",Backlog!$G:$G,"S8",Backlog!$A:$A,"Task") | M11: =SUMIFS(Backlog!$H:$H,Backlog!$F:$F,"TL",Backlog!$G:$G,"S8",Backlog!$A:$A,"Task") | N11: =SUM(F11:M11)
A12: S9 | B12: 46300 | C12: 46311 | D12: Group 2 wave 1 (models 3-5) live; dashboards validated with ABSA; cost dashboard | F12: =SUMIFS(Backlog!$H:$H,Backlog!$F:$F,"AWS",Backlog!$G:$G,"S9",Backlog!$A:$A,"Task") | G12: =SUMIFS(Backlog!$H:$H,Backlog!$F:$F,"AWS2",Backlog!$G:$G,"S9",Backlog!$A:$A,"Task") | H12: =SUMIFS(Backlog!$H:$H,Backlog!$F:$F,"DE",Backlog!$G:$G,"S9",Backlog!$A:$A,"Task") | I12: =SUMIFS(Backlog!$H:$H,Backlog!$F:$F,"SAS",Backlog!$G:$G,"S9",Backlog!$A:$A,"Task") | J12: =SUMIFS(Backlog!$H:$H,Backlog!$F:$F,"SAS2",Backlog!$G:$G,"S9",Backlog!$A:$A,"Task") | K12: =SUMIFS(Backlog!$H:$H,Backlog!$F:$F,"SAS3",Backlog!$G:$G,"S9",Backlog!$A:$A,"Task") | L12: =SUMIFS(Backlog!$H:$H,Backlog!$F:$F,"DevOps",Backlog!$G:$G,"S9",Backlog!$A:$A,"Task") | M12: =SUMIFS(Backlog!$H:$H,Backlog!$F:$F,"TL",Backlog!$G:$G,"S9",Backlog!$A:$A,"Task") | N12: =SUM(F12:M12)
A13: S10 | B13: 46314 | C13: 46325 | D13: Group 2 wave 2 (models 6-8) live; output delivery automated | F13: =SUMIFS(Backlog!$H:$H,Backlog!$F:$F,"AWS",Backlog!$G:$G,"S10",Backlog!$A:$A,"Task") | G13: =SUMIFS(Backlog!$H:$H,Backlog!$F:$F,"AWS2",Backlog!$G:$G,"S10",Backlog!$A:$A,"Task") | H13: =SUMIFS(Backlog!$H:$H,Backlog!$F:$F,"DE",Backlog!$G:$G,"S10",Backlog!$A:$A,"Task") | I13: =SUMIFS(Backlog!$H:$H,Backlog!$F:$F,"SAS",Backlog!$G:$G,"S10",Backlog!$A:$A,"Task") | J13: =SUMIFS(Backlog!$H:$H,Backlog!$F:$F,"SAS2",Backlog!$G:$G,"S10",Backlog!$A:$A,"Task") | K13: =SUMIFS(Backlog!$H:$H,Backlog!$F:$F,"SAS3",Backlog!$G:$G,"S10",Backlog!$A:$A,"Task") | L13: =SUMIFS(Backlog!$H:$H,Backlog!$F:$F,"DevOps",Backlog!$G:$G,"S10",Backlog!$A:$A,"Task") | M13: =SUMIFS(Backlog!$H:$H,Backlog!$F:$F,"TL",Backlog!$G:$G,"S10",Backlog!$A:$A,"Task") | N13: =SUM(F13:M13)
A14: S11 | B14: 46328 | C14: 46339 | D14: Group 2 wave 3 (models 9-10) live - ALL 10 MODELS SCORING; runbooks; DR verified | E14: All 10 models live | F14: =SUMIFS(Backlog!$H:$H,Backlog!$F:$F,"AWS",Backlog!$G:$G,"S11",Backlog!$A:$A,"Task") | G14: =SUMIFS(Backlog!$H:$H,Backlog!$F:$F,"AWS2",Backlog!$G:$G,"S11",Backlog!$A:$A,"Task") | H14: =SUMIFS(Backlog!$H:$H,Backlog!$F:$F,"DE",Backlog!$G:$G,"S11",Backlog!$A:$A,"Task") | I14: =SUMIFS(Backlog!$H:$H,Backlog!$F:$F,"SAS",Backlog!$G:$G,"S11",Backlog!$A:$A,"Task") | J14: =SUMIFS(Backlog!$H:$H,Backlog!$F:$F,"SAS2",Backlog!$G:$G,"S11",Backlog!$A:$A,"Task") | K14: =SUMIFS(Backlog!$H:$H,Backlog!$F:$F,"SAS3",Backlog!$G:$G,"S11",Backlog!$A:$A,"Task") | L14: =SUMIFS(Backlog!$H:$H,Backlog!$F:$F,"DevOps",Backlog!$G:$G,"S11",Backlog!$A:$A,"Task") | M14: =SUMIFS(Backlog!$H:$H,Backlog!$F:$F,"TL",Backlog!$G:$G,"S11",Backlog!$A:$A,"Task") | N14: =SUM(F14:M14)
A15: S12 | B15: 46342 | C15: 46353 | D15: HARDENING ONLY (no new models): GROUP 2 SIGN-OFF; handover; hypercare; steady-state go-live | E15: *** GROUP 2 SIGN-OFF + GO-LIVE *** | F15: =SUMIFS(Backlog!$H:$H,Backlog!$F:$F,"AWS",Backlog!$G:$G,"S12",Backlog!$A:$A,"Task") | G15: =SUMIFS(Backlog!$H:$H,Backlog!$F:$F,"AWS2",Backlog!$G:$G,"S12",Backlog!$A:$A,"Task") | H15: =SUMIFS(Backlog!$H:$H,Backlog!$F:$F,"DE",Backlog!$G:$G,"S12",Backlog!$A:$A,"Task") | I15: =SUMIFS(Backlog!$H:$H,Backlog!$F:$F,"SAS",Backlog!$G:$G,"S12",Backlog!$A:$A,"Task") | J15: =SUMIFS(Backlog!$H:$H,Backlog!$F:$F,"SAS2",Backlog!$G:$G,"S12",Backlog!$A:$A,"Task") | K15: =SUMIFS(Backlog!$H:$H,Backlog!$F:$F,"SAS3",Backlog!$G:$G,"S12",Backlog!$A:$A,"Task") | L15: =SUMIFS(Backlog!$H:$H,Backlog!$F:$F,"DevOps",Backlog!$G:$G,"S12",Backlog!$A:$A,"Task") | M15: =SUMIFS(Backlog!$H:$H,Backlog!$F:$F,"TL",Backlog!$G:$G,"S12",Backlog!$A:$A,"Task") | N15: =SUM(F15:M15)

Sheet Role Load
A1: Role Load vs Capacity (effort-days per sprint)
A3: Role | B3: S1 | C3: S2 | D3: S3 | E3: S4 | F3: S5 | G3: S6 | H3: S7 | I3: S8 | J3: S9 | K3: S10 | L3: S11 | M3: S12
A4: AWS - AWS/MLOps Eng #1 - Foundation & Infra | B4: =SUMIFS(Backlog!$H:$H,Backlog!$F:$F,"AWS",Backlog!$G:$G,"S1",Backlog!$A:$A,"Task") | C4: =SUMIFS(Backlog!$H:$H,Backlog!$F:$F,"AWS",Backlog!$G:$G,"S2",Backlog!$A:$A,"Task") | D4: =SUMIFS(Backlog!$H:$H,Backlog!$F:$F,"AWS",Backlog!$G:$G,"S3",Backlog!$A:$A,"Task") | E4: =SUMIFS(Backlog!$H:$H,Backlog!$F:$F,"AWS",Backlog!$G:$G,"S4",Backlog!$A:$A,"Task") | F4: =SUMIFS(Backlog!$H:$H,Backlog!$F:$F,"AWS",Backlog!$G:$G,"S5",Backlog!$A:$A,"Task") | G4: =SUMIFS(Backlog!$H:$H,Backlog!$F:$F,"AWS",Backlog!$G:$G,"S6",Backlog!$A:$A,"Task") | H4: =SUMIFS(Backlog!$H:$H,Backlog!$F:$F,"AWS",Backlog!$G:$G,"S7",Backlog!$A:$A,"Task") | I4: =SUMIFS(Backlog!$H:$H,Backlog!$F:$F,"AWS",Backlog!$G:$G,"S8",Backlog!$A:$A,"Task") | J4: =SUMIFS(Backlog!$H:$H,Backlog!$F:$F,"AWS",Backlog!$G:$G,"S9",Backlog!$A:$A,"Task") | K4: =SUMIFS(Backlog!$H:$H,Backlog!$F:$F,"AWS",Backlog!$G:$G,"S10",Backlog!$A:$A,"Task") | L4: =SUMIFS(Backlog!$H:$H,Backlog!$F:$F,"AWS",Backlog!$G:$G,"S11",Backlog!$A:$A,"Task") | M4: =SUMIFS(Backlog!$H:$H,Backlog!$F:$F,"AWS",Backlog!$G:$G,"S12",Backlog!$A:$A,"Task")
A5: AWS2 - AWS/MLOps Eng #2 - Platform, Compute & MLOps | B5: =SUMIFS(Backlog!$H:$H,Backlog!$F:$F,"AWS2",Backlog!$G:$G,"S1",Backlog!$A:$A,"Task") | C5: =SUMIFS(Backlog!$H:$H,Backlog!$F:$F,"AWS2",Backlog!$G:$G,"S2",Backlog!$A:$A,"Task") | D5: =SUMIFS(Backlog!$H:$H,Backlog!$F:$F,"AWS2",Backlog!$G:$G,"S3",Backlog!$A:$A,"Task") | E5: =SUMIFS(Backlog!$H:$H,Backlog!$F:$F,"AWS2",Backlog!$G:$G,"S4",Backlog!$A:$A,"Task") | F5: =SUMIFS(Backlog!$H:$H,Backlog!$F:$F,"AWS2",Backlog!$G:$G,"S5",Backlog!$A:$A,"Task") | G5: =SUMIFS(Backlog!$H:$H,Backlog!$F:$F,"AWS2",Backlog!$G:$G,"S6",Backlog!$A:$A,"Task") | H5: =SUMIFS(Backlog!$H:$H,Backlog!$F:$F,"AWS2",Backlog!$G:$G,"S7",Backlog!$A:$A,"Task") | I5: =SUMIFS(Backlog!$H:$H,Backlog!$F:$F,"AWS2",Backlog!$G:$G,"S8",Backlog!$A:$A,"Task") | J5: =SUMIFS(Backlog!$H:$H,Backlog!$F:$F,"AWS2",Backlog!$G:$G,"S9",Backlog!$A:$A,"Task") | K5: =SUMIFS(Backlog!$H:$H,Backlog!$F:$F,"AWS2",Backlog!$G:$G,"S10",Backlog!$A:$A,"Task") | L5: =SUMIFS(Backlog!$H:$H,Backlog!$F:$F,"AWS2",Backlog!$G:$G,"S11",Backlog!$A:$A,"Task") | M5: =SUMIFS(Backlog!$H:$H,Backlog!$F:$F,"AWS2",Backlog!$G:$G,"S12",Backlog!$A:$A,"Task")
A6: DE - Data Engineer | B6: =SUMIFS(Backlog!$H:$H,Backlog!$F:$F,"DE",Backlog!$G:$G,"S1",Backlog!$A:$A,"Task") | C6: =SUMIFS(Backlog!$H:$H,Backlog!$F:$F,"DE",Backlog!$G:$G,"S2",Backlog!$A:$A,"Task") | D6: =SUMIFS(Backlog!$H:$H,Backlog!$F:$F,"DE",Backlog!$G:$G,"S3",Backlog!$A:$A,"Task") | E6: =SUMIFS(Backlog!$H:$H,Backlog!$F:$F,"DE",Backlog!$G:$G,"S4",Backlog!$A:$A,"Task") | F6: =SUMIFS(Backlog!$H:$H,Backlog!$F:$F,"DE",Backlog!$G:$G,"S5",Backlog!$A:$A,"Task") | G6: =SUMIFS(Backlog!$H:$H,Backlog!$F:$F,"DE",Backlog!$G:$G,"S6",Backlog!$A:$A,"Task") | H6: =SUMIFS(Backlog!$H:$H,Backlog!$F:$F,"DE",Backlog!$G:$G,"S7",Backlog!$A:$A,"Task") | I6: =SUMIFS(Backlog!$H:$H,Backlog!$F:$F,"DE",Backlog!$G:$G,"S8",Backlog!$A:$A,"Task") | J6: =SUMIFS(Backlog!$H:$H,Backlog!$F:$F,"DE",Backlog!$G:$G,"S9",Backlog!$A:$A,"Task") | K6: =SUMIFS(Backlog!$H:$H,Backlog!$F:$F,"DE",Backlog!$G:$G,"S10",Backlog!$A:$A,"Task") | L6: =SUMIFS(Backlog!$H:$H,Backlog!$F:$F,"DE",Backlog!$G:$G,"S11",Backlog!$A:$A,"Task") | M6: =SUMIFS(Backlog!$H:$H,Backlog!$F:$F,"DE",Backlog!$G:$G,"S12",Backlog!$A:$A,"Task")
A7: SAS - SAS Developer #1 (Model 1 / Group 2) | B7: =SUMIFS(Backlog!$H:$H,Backlog!$F:$F,"SAS",Backlog!$G:$G,"S1",Backlog!$A:$A,"Task") | C7: =SUMIFS(Backlog!$H:$H,Backlog!$F:$F,"SAS",Backlog!$G:$G,"S2",Backlog!$A:$A,"Task") | D7: =SUMIFS(Backlog!$H:$H,Backlog!$F:$F,"SAS",Backlog!$G:$G,"S3",Backlog!$A:$A,"Task") | E7: =SUMIFS(Backlog!$H:$H,Backlog!$F:$F,"SAS",Backlog!$G:$G,"S4",Backlog!$A:$A,"Task") | F7: =SUMIFS(Backlog!$H:$H,Backlog!$F:$F,"SAS",Backlog!$G:$G,"S5",Backlog!$A:$A,"Task") | G7: =SUMIFS(Backlog!$H:$H,Backlog!$F:$F,"SAS",Backlog!$G:$G,"S6",Backlog!$A:$A,"Task") | H7: =SUMIFS(Backlog!$H:$H,Backlog!$F:$F,"SAS",Backlog!$G:$G,"S7",Backlog!$A:$A,"Task") | I7: =SUMIFS(Backlog!$H:$H,Backlog!$F:$F,"SAS",Backlog!$G:$G,"S8",Backlog!$A:$A,"Task") | J7: =SUMIFS(Backlog!$H:$H,Backlog!$F:$F,"SAS",Backlog!$G:$G,"S9",Backlog!$A:$A,"Task") | K7: =SUMIFS(Backlog!$H:$H,Backlog!$F:$F,"SAS",Backlog!$G:$G,"S10",Backlog!$A:$A,"Task") | L7: =SUMIFS(Backlog!$H:$H,Backlog!$F:$F,"SAS",Backlog!$G:$G,"S11",Backlog!$A:$A,"Task") | M7: =SUMIFS(Backlog!$H:$H,Backlog!$F:$F,"SAS",Backlog!$G:$G,"S12",Backlog!$A:$A,"Task")
A8: SAS2 - SAS Developer #2 (Model 2 / Group 2) | B8: =SUMIFS(Backlog!$H:$H,Backlog!$F:$F,"SAS2",Backlog!$G:$G,"S1",Backlog!$A:$A,"Task") | C8: =SUMIFS(Backlog!$H:$H,Backlog!$F:$F,"SAS2",Backlog!$G:$G,"S2",Backlog!$A:$A,"Task") | D8: =SUMIFS(Backlog!$H:$H,Backlog!$F:$F,"SAS2",Backlog!$G:$G,"S3",Backlog!$A:$A,"Task") | E8: =SUMIFS(Backlog!$H:$H,Backlog!$F:$F,"SAS2",Backlog!$G:$G,"S4",Backlog!$A:$A,"Task") | F8: =SUMIFS(Backlog!$H:$H,Backlog!$F:$F,"SAS2",Backlog!$G:$G,"S5",Backlog!$A:$A,"Task") | G8: =SUMIFS(Backlog!$H:$H,Backlog!$F:$F,"SAS2",Backlog!$G:$G,"S6",Backlog!$A:$A,"Task") | H8: =SUMIFS(Backlog!$H:$H,Backlog!$F:$F,"SAS2",Backlog!$G:$G,"S7",Backlog!$A:$A,"Task") | I8: =SUMIFS(Backlog!$H:$H,Backlog!$F:$F,"SAS2",Backlog!$G:$G,"S8",Backlog!$A:$A,"Task") | J8: =SUMIFS(Backlog!$H:$H,Backlog!$F:$F,"SAS2",Backlog!$G:$G,"S9",Backlog!$A:$A,"Task") | K8: =SUMIFS(Backlog!$H:$H,Backlog!$F:$F,"SAS2",Backlog!$G:$G,"S10",Backlog!$A:$A,"Task") | L8: =SUMIFS(Backlog!$H:$H,Backlog!$F:$F,"SAS2",Backlog!$G:$G,"S11",Backlog!$A:$A,"Task") | M8: =SUMIFS(Backlog!$H:$H,Backlog!$F:$F,"SAS2",Backlog!$G:$G,"S12",Backlog!$A:$A,"Task")
A9: SAS3 - SAS Developer #3 (Group 2, from S8) | B9: =SUMIFS(Backlog!$H:$H,Backlog!$F:$F,"SAS3",Backlog!$G:$G,"S1",Backlog!$A:$A,"Task") | C9: =SUMIFS(Backlog!$H:$H,Backlog!$F:$F,"SAS3",Backlog!$G:$G,"S2",Backlog!$A:$A,"Task") | D9: =SUMIFS(Backlog!$H:$H,Backlog!$F:$F,"SAS3",Backlog!$G:$G,"S3",Backlog!$A:$A,"Task") | E9: =SUMIFS(Backlog!$H:$H,Backlog!$F:$F,"SAS3",Backlog!$G:$G,"S4",Backlog!$A:$A,"Task") | F9: =SUMIFS(Backlog!$H:$H,Backlog!$F:$F,"SAS3",Backlog!$G:$G,"S5",Backlog!$A:$A,"Task") | G9: =SUMIFS(Backlog!$H:$H,Backlog!$F:$F,"SAS3",Backlog!$G:$G,"S6",Backlog!$A:$A,"Task") | H9: =SUMIFS(Backlog!$H:$H,Backlog!$F:$F,"SAS3",Backlog!$G:$G,"S7",Backlog!$A:$A,"Task") | I9: =SUMIFS(Backlog!$H:$H,Backlog!$F:$F,"SAS3",Backlog!$G:$G,"S8",Backlog!$A:$A,"Task") | J9: =SUMIFS(Backlog!$H:$H,Backlog!$F:$F,"SAS3",Backlog!$G:$G,"S9",Backlog!$A:$A,"Task") | K9: =SUMIFS(Backlog!$H:$H,Backlog!$F:$F,"SAS3",Backlog!$G:$G,"S10",Backlog!$A:$A,"Task") | L9: =SUMIFS(Backlog!$H:$H,Backlog!$F:$F,"SAS3",Backlog!$G:$G,"S11",Backlog!$A:$A,"Task") | M9: =SUMIFS(Backlog!$H:$H,Backlog!$F:$F,"SAS3",Backlog!$G:$G,"S12",Backlog!$A:$A,"Task")
A10: DevOps - DevOps Engineer | B10: =SUMIFS(Backlog!$H:$H,Backlog!$F:$F,"DevOps",Backlog!$G:$G,"S1",Backlog!$A:$A,"Task") | C10: =SUMIFS(Backlog!$H:$H,Backlog!$F:$F,"DevOps",Backlog!$G:$G,"S2",Backlog!$A:$A,"Task") | D10: =SUMIFS(Backlog!$H:$H,Backlog!$F:$F,"DevOps",Backlog!$G:$G,"S3",Backlog!$A:$A,"Task") | E10: =SUMIFS(Backlog!$H:$H,Backlog!$F:$F,"DevOps",Backlog!$G:$G,"S4",Backlog!$A:$A,"Task") | F10: =SUMIFS(Backlog!$H:$H,Backlog!$F:$F,"DevOps",Backlog!$G:$G,"S5",Backlog!$A:$A,"Task") | G10: =SUMIFS(Backlog!$H:$H,Backlog!$F:$F,"DevOps",Backlog!$G:$G,"S6",Backlog!$A:$A,"Task") | H10: =SUMIFS(Backlog!$H:$H,Backlog!$F:$F,"DevOps",Backlog!$G:$G,"S7",Backlog!$A:$A,"Task") | I10: =SUMIFS(Backlog!$H:$H,Backlog!$F:$F,"DevOps",Backlog!$G:$G,"S8",Backlog!$A:$A,"Task") | J10: =SUMIFS(Backlog!$H:$H,Backlog!$F:$F,"DevOps",Backlog!$G:$G,"S9",Backlog!$A:$A,"Task") | K10: =SUMIFS(Backlog!$H:$H,Backlog!$F:$F,"DevOps",Backlog!$G:$G,"S10",Backlog!$A:$A,"Task") | L10: =SUMIFS(Backlog!$H:$H,Backlog!$F:$F,"DevOps",Backlog!$G:$G,"S11",Backlog!$A:$A,"Task") | M10: =SUMIFS(Backlog!$H:$H,Backlog!$F:$F,"DevOps",Backlog!$G:$G,"S12",Backlog!$A:$A,"Task")
A11: TL - Tech Lead (Vishnu) | B11: =SUMIFS(Backlog!$H:$H,Backlog!$F:$F,"TL",Backlog!$G:$G,"S1",Backlog!$A:$A,"Task") | C11: =SUMIFS(Backlog!$H:$H,Backlog!$F:$F,"TL",Backlog!$G:$G,"S2",Backlog!$A:$A,"Task") | D11: =SUMIFS(Backlog!$H:$H,Backlog!$F:$F,"TL",Backlog!$G:$G,"S3",Backlog!$A:$A,"Task") | E11: =SUMIFS(Backlog!$H:$H,Backlog!$F:$F,"TL",Backlog!$G:$G,"S4",Backlog!$A:$A,"Task") | F11: =SUMIFS(Backlog!$H:$H,Backlog!$F:$F,"TL",Backlog!$G:$G,"S5",Backlog!$A:$A,"Task") | G11: =SUMIFS(Backlog!$H:$H,Backlog!$F:$F,"TL",Backlog!$G:$G,"S6",Backlog!$A:$A,"Task") | H11: =SUMIFS(Backlog!$H:$H,Backlog!$F:$F,"TL",Backlog!$G:$G,"S7",Backlog!$A:$A,"Task") | I11: =SUMIFS(Backlog!$H:$H,Backlog!$F:$F,"TL",Backlog!$G:$G,"S8",Backlog!$A:$A,"Task") | J11: =SUMIFS(Backlog!$H:$H,Backlog!$F:$F,"TL",Backlog!$G:$G,"S9",Backlog!$A:$A,"Task") | K11: =SUMIFS(Backlog!$H:$H,Backlog!$F:$F,"TL",Backlog!$G:$G,"S10",Backlog!$A:$A,"Task") | L11: =SUMIFS(Backlog!$H:$H,Backlog!$F:$F,"TL",Backlog!$G:$G,"S11",Backlog!$A:$A,"Task") | M11: =SUMIFS(Backlog!$H:$H,Backlog!$F:$F,"TL",Backlog!$G:$G,"S12",Backlog!$A:$A,"Task")
A12: Capacity (cap) | B12: 8 / TL 6 | C12: 8 / TL 6 | D12: 8 / TL 6 | E12: 8 / TL 6 | F12: 8 / TL 6 | G12: 8 / TL 6 | H12: 8 / TL 6 | I12: 8 / TL 6 | J12: 8 / TL 6 | K12: 8 / TL 6 | L12: 8 / TL 6 | M12: 8 / TL 6
A14: Green = loaded within capacity | Yellow = near cap (<=1d slack) | Red = over capacity (re-plan) | Grey = off-team (SAS3 before S8) | Light = idle. Fills reflect the committed plan; values recalc live via SUMIFS. AWS2 idle late = redeploy lever (see README).

Sheet Per-Model Tracker
A1: Per-Model Onboarding Tracker (10 models)
A3: Model | B3: Group / Wave | C3: Sprint(s) | D3: SAS Owner | E3: Cadence | F3: Contract | G3: Review | H3: Optimize | I3: Package | J3: Deploy | K3: Reconcile | L3: Impl doc | M3: PIR | N3: Sign-off
A4: Model 1 | B4: Group 1 | C4: S2-S8 | D4: SAS | E4: TBD (ABSA) | F4: Planned | G4: Planned | H4: Planned | I4: Planned | J4: Planned | K4: Planned | L4: Planned | M4: Planned | N4: Planned
A5: Model 2 | B5: Group 1 | C5: S2-S8 | D5: SAS2 | E5: TBD (ABSA) | F5: Planned | G5: Planned | H5: Planned | I5: Planned | J5: Planned | K5: Planned | L5: Planned | M5: Planned | N5: Planned
A6: Model 3 | B6: Group 2 W1 | C6: S9 | D6: SAS | E6: TBD | F6: Planned | G6: Planned | H6: Planned | I6: Planned | J6: Planned | K6: Planned | L6: Planned | M6: Planned | N6: Planned
A7: Model 4 | B7: Group 2 W1 | C7: S9 | D7: SAS2 | E7: TBD | F7: Planned | G7: Planned | H7: Planned | I7: Planned | J7: Planned | K7: Planned | L7: Planned | M7: Planned | N7: Planned
A8: Model 5 | B8: Group 2 W1 | C8: S9 | D8: SAS3 | E8: TBD | F8: Planned | G8: Planned | H8: Planned | I8: Planned | J8: Planned | K8: Planned | L8: Planned | M8: Planned | N8: Planned
A9: Model 6 | B9: Group 2 W2 | C9: S10 | D9: SAS | E9: TBD | F9: Planned | G9: Planned | H9: Planned | I9: Planned | J9: Planned | K9: Planned | L9: Planned | M9: Planned | N9: Planned
A10: Model 7 | B10: Group 2 W2 | C10: S10 | D10: SAS2 | E10: TBD | F10: Planned | G10: Planned | H10: Planned | I10: Planned | J10: Planned | K10: Planned | L10: Planned | M10: Planned | N10: Planned
A11: Model 8 | B11: Group 2 W2 | C11: S10 | D11: SAS3 | E11: TBD | F11: Planned | G11: Planned | H11: Planned | I11: Planned | J11: Planned | K11: Planned | L11: Planned | M11: Planned | N11: Planned
A12: Model 9 | B12: Group 2 W3 | C12: S11 | D12: SAS | E12: TBD | F12: Planned | G12: Planned | H12: Planned | I12: Planned | J12: Planned | K12: Planned | L12: Planned | M12: Planned | N12: Planned
A13: Model 10 | B13: Group 2 W3 | C13: S11 | D13: SAS2 | E13: TBD | F13: Planned | G13: Planned | H13: Planned | I13: Planned | J13: Planned | K13: Planned | L13: Planned | M13: Planned | N13: Planned
A15: Stages map to backlog tasks. Group 1 (models 1-2) is the proof; Group 2 (3-10) uses the template, 2 models/sprint split across SAS + SAS2. Update each stage cell to Done/WIP/Blocked.

Sheet Governance & Cadence
A1: Governance & Cadence
A3: Ceremonies
A4: Ceremony | B4: When | C4: Who | D4: Outcome
A5: Daily standup | B5: Every working day, 15 min | C5: All | D5: Blockers surfaced same-day
A6: Sprint planning | B6: 1st Monday of each sprint, 2h | C6: All | D6: Sprint backlog committed
A7: Backlog refinement | B7: Mid-sprint Wednesday, 1h | C7: TL + leads | D7: Next sprint stories Ready
A8: Sprint review + demo | B8: 2nd Friday, 1h | C8: All + ABSA optional | D8: Working increment shown
A9: Retrospective | B9: 2nd Friday, 45 min | C9: All | D9: Actions logged + owned
A11: Decision & Sign-off Checkpoints
A12: Checkpoint | B12: Sprint | C12: Target date | D12: Owner | E12: Gate criteria
A13: Kickoff + SPOCs confirmed | B13: S1 | C13: 46199 | D13: TL | E13: Charter + SPOCs signed
A14: Jenkins cutover (GHA retired) | B14: S3 | C14: 46227 | D14: DevOps | E14: Jenkins sole CI gate; branch protection flipped
A15: Registry live in dev | B15: S4 | C15: 46241 | D15: AWS | E15: SigV4 register smoke green
A16: S5 CAPACITY REVIEW (confirm 3rd SAS + AWS ramp-down) | B16: S5 | C16: 46255 | D16: TL | E16: Confirm SAS3 onboarding S8; plan AWS redeploy after S7
A17: Dress rehearsal pass | B17: S6 | C17: 46269 | D17: TL | E17: Full chain on real AWS, models 1-2
A18: G1 production readiness (go/no-go) | B18: S8 | C18: 46297 | D18: DevOps | E18: Readiness checklist + cutover rehearsal clean
A19: GROUP 1 ABSA SIGN-OFF | B19: S8 | C19: 46297 | D19: ABSA Risk | E19: Written sign-off; PIR + audit pack accepted
A20: Steering checkpoint (mid-program) | B20: S6 | C20: 46269 | D20: TL | E20: Status + risk review with ABSA + EXL sponsors
A21: ALL 10 MODELS LIVE (Group 2 onboarding complete) | B21: S11 | C21: 46339 | D21: TL | E21: Models 3-10 scoring; S12 reserved for hardening
A22: Steering checkpoint (pre-go-live) | B22: S11 | C22: 46339 | D22: TL | E22: Go-live readiness review
A23: GROUP 2 SIGN-OFF + go-live | B23: S12 | C23: 46353 | D23: ABSA Risk | E23: All 10 models signed off; steady-state begins

Sheet RAID Log
A1: RAID Log - Risks / Assumptions / Issues / Dependencies
A3: Type | B3: ID | C3: Item | D3: Owner | E3: Sprint / Prob-Impact | F3: Status / Mitigation
A4: Dependency | B4: DEP-01 | C4: AWS account IDs (3 EXL + ABSA receiving) | D4: ABSA | E4: T-0304 (S2) | F4: Open - bootstrap blocked; slips downstream day-for-day
A5: Dependency | B5: DEP-02 | C5: IAM principal ARNs (kms:Verify / s3:GetObject) | D5: ABSA | E5: T-0312 (S4) | F5: Open - cross-account verify untestable
A6: Dependency | B6: DEP-03 | C6: SAS runtime Docker image + license | D6: ABSA | E6: T-0503/0504 (S2-S3) | F6: Open - SAS validation stays structural-only
A7: Dependency | B7: DEP-04 | C7: PIR system API/feed contract | D7: ABSA | E7: T-0411 (S5) | F7: Open - pir.yaml hand-maintained
A8: Dependency | B8: DEP-05 | C8: Data movement decision (S3 replication vs SFTP) | D8: ABSA | E8: T-0318/0906 (S4/S8) | F8: Open - transfer + delivery blocked
A9: Dependency | B9: DEP-06 | C9: CAB / IVU API contract | D9: ABSA | E9: T-0701 (S5) | F9: Open - change workflow manual
A10: Dependency | B10: DEP-07 | C10: Network connectivity choice (peering/TGW/PrivateLink) | D10: ABSA | E10: T-0307 (S3) | F10: Open - data plane blocked
A11: Dependency | B11: DEP-08 | C11: Approved model docs + code + benchmarks (1-2 first) | D11: ABSA | E11: T-0403/0505 (S2) | F11: Open - SAS + DE model work blocked
A12: Dependency | B12: DEP-09 | C12: LLM data-processing terms (Azure OpenAI / Anthropic): no-retention DPA + region | D12: ABSA | E12: T-1407/1403 (S5/S7) | F12: Open - gates first real IDG run (ADR-0012); manual impl-doc fallback otherwise
A13: Risk | B13: RISK-01 | C13: ABSA account onboarding delayed past S2 | D13: TL | E13: High / Med | F13: 2 AWS engineers + ~2d/sprint slack in S2-S5 absorb a slip; pre-stage TF + tfvars; LocalStack keeps CI green; escalate end S1
A14: Risk | B14: RISK-02 | C14: Group 1 sign-off (S8) slips, cascades to Group 2 | D14: ABSA Risk | E14: Med / High | F14: Models 1-2 run in PARALLEL (2 SAS) from S2; dress rehearsal S6; defect buffer S7-S8
... A25: Issue | B25: ISS-00 | C25: (none logged yet - populate during delivery) | D25: TL | E25: - | F25: -
A27: Internal prerequisites (Sprint 0 / Sprint 1)
A28: ID | B28: Item | C28: Owner | D28: When
A29: PRE-01 | B29: Jira/ADO project + board created | C29: TL | D29: Before S1 planning
A30: PRE-02 | B30: GitHub repo write access for all engineers + CODEOWNERS updated | C30: TL | D30: Before S1 day 1
A31: PRE-03 | B31: Jenkins admin access for DevOps engineer | C31: DevOps | D31: Before S1 day 1
A32: PRE-04 | B32: AWS sandbox account access for AWS engineer | C32: AWS | D32: Before S1 day 1
A33: PRE-05 | B33: Dev machines: uv, Docker Desktop, Terraform 1.9.5, Python 3.12 | C33: All | D33: S1 day 1-2
A34: PRE-06 | B34: Slack/Teams channel + ceremony invites | C34: TL | D34: Before S1 planning
A35: PRE-07 | B35: SAS desktop/dev license (interim until ABSA runtime) | C35: SAS | D35: S1

Sheet Dashboard
A1: Delivery Dashboard
A3: Tasks by Status | D3: Effort by Role (d)
A4: Status | B4: Count | D4: Role | E4: Days
A5: Planned | B5: =COUNTIFS(Backlog!$M:$M,"Planned",Backlog!$A:$A,"Task") | D5: AWS | E5: =SUMIFS(Backlog!$H:$H,Backlog!$F:$F,"AWS",Backlog!$A:$A,"Task")
A6: In Progress | B6: =COUNTIFS(Backlog!$M:$M,"In Progress",Backlog!$A:$A,"Task") | D6: AWS2 | E6: =SUMIFS(Backlog!$H:$H,Backlog!$F:$F,"AWS2",Backlog!$A:$A,"Task")
A7: Done | B7: =COUNTIFS(Backlog!$M:$M,"Done",Backlog!$A:$A,"Task") | D7: DE | E7: =SUMIFS(Backlog!$H:$H,Backlog!$F:$F,"DE",Backlog!$A:$A,"Task")
A8: Blocked | B8: =COUNTIFS(Backlog!$M:$M,"Blocked",Backlog!$A:$A,"Task") | D8: SAS | E8: =SUMIFS(Backlog!$H:$H,Backlog!$F:$F,"SAS",Backlog!$A:$A,"Task")
D9: SAS2 | E9: =SUMIFS(Backlog!$H:$H,Backlog!$F:$F,"SAS2",Backlog!$A:$A,"Task")
D10: SAS3 | E10: =SUMIFS(Backlog!$H:$H,Backlog!$F:$F,"SAS3",Backlog!$A:$A,"Task")
D11: DevOps | E11: =SUMIFS(Backlog!$H:$H,Backlog!$F:$F,"DevOps",Backlog!$A:$A,"Task")
D12: TL | E12: =SUMIFS(Backlog!$H:$H,Backlog!$F:$F,"TL",Backlog!$A:$A,"Task")
A13: Tasks + Effort by Epic
A14: Epic | B14: Title | C14: Tasks | D14: Effort (d) | E14: Done
A15: E01 | B15: Team Onboarding & Governance | C15: =COUNTIFS(Backlog!$D:$D,"E01",Backlog!$A:$A,"Task") | D15: =SUMIFS(Backlog!$H:$H,Backlog!$D:$D,"E01",Backlog!$A:$A,"Task") | E15: =COUNTIFS(Backlog!$D:$D,"E01",Backlog!$A:$A,"Task",Backlog!$M:$M,"Done")
A16: E02 | B16: CI/CD on Existing Jenkins | C16: =COUNTIFS(Backlog!$D:$D,"E02",Backlog!$A:$A,"Task") | D16: =SUMIFS(Backlog!$H:$H,Backlog!$D:$D,"E02",Backlog!$A:$A,"Task") | E16: =COUNTIFS(Backlog!$D:$D,"E02",Backlog!$A:$A,"Task",Backlog!$M:$M,"Done")
A17: E03 | B17: AWS Foundation (Real Accounts) | C17: =COUNTIFS(Backlog!$D:$D,"E03",Backlog!$A:$A,"Task") | D17: =SUMIFS(Backlog!$H:$H,Backlog!$D:$D,"E03",Backlog!$A:$A,"Task") | E17: =COUNTIFS(Backlog!$D:$D,"E03",Backlog!$A:$A,"Task",Backlog!$M:$M,"Done")
A18: E04 | B18: Data Engineering & Quality | C18: =COUNTIFS(Backlog!$D:$D,"E04",Backlog!$A:$A,"Task") | D18: =SUMIFS(Backlog!$H:$H,Backlog!$D:$D,"E04",Backlog!$A:$A,"Task") | E18: =COUNTIFS(Backlog!$D:$D,"E04",Backlog!$A:$A,"Task",Backlog!$M:$M,"Done")
A19: E05 | B19: SAS Model Engineering - Standards & Tooling | C19: =COUNTIFS(Backlog!$D:$D,"E05",Backlog!$A:$A,"Task") | D19: =SUMIFS(Backlog!$H:$H,Backlog!$D:$D,"E05",Backlog!$A:$A,"Task") | E19: =COUNTIFS(Backlog!$D:$D,"E05",Backlog!$A:$A,"Task",Backlog!$M:$M,"Done")
A20: E06 | B20: ML Compute & Pipeline Execution | C20: =COUNTIFS(Backlog!$D:$D,"E06",Backlog!$A:$A,"Task") | D20: =SUMIFS(Backlog!$H:$H,Backlog!$D:$D,"E06",Backlog!$A:$A,"Task") | E20: =COUNTIFS(Backlog!$D:$D,"E06",Backlog!$A:$A,"Task",Backlog!$M:$M,"Done")
A21: E07 | B21: Security, Controls & Compliance | C21: =COUNTIFS(Backlog!$D:$D,"E07",Backlog!$A:$A,"Task") | D21: =SUMIFS(Backlog!$H:$H,Backlog!$D:$D,"E07",Backlog!$A:$A,"Task") | E21: =COUNTIFS(Backlog!$D:$D,"E07",Backlog!$A:$A,"Task",Backlog!$M:$M,"Done")
A22: E08 | B22: Group 1 - Model Onboarding (Models 1-2) | C22: =COUNTIFS(Backlog!$D:$D,"E08",Backlog!$A:$A,"Task") | D22: =SUMIFS(Backlog!$H:$H,Backlog!$D:$D,"E08",Backlog!$A:$A,"Task") | E22: =COUNTIFS(Backlog!$D:$D,"E08",Backlog!$A:$A,"Task",Backlog!$M:$M,"Done")
A23: E09 | B23: Observability, Dashboards & Delivery | C23: =COUNTIFS(Backlog!$D:$D,"E09",Backlog!$A:$A,"Task") | D23: =SUMIFS(Backlog!$H:$H,Backlog!$D:$D,"E09",Backlog!$A:$A,"Task") | E23: =COUNTIFS(Backlog!$D:$D,"E09",Backlog!$A:$A,"Task",Backlog!$M:$M,"Done")
A24: E10 | B24: Group 2 - Scale-Out (Models 3-10) | C24: =COUNTIFS(Backlog!$D:$D,"E10",Backlog!$A:$A,"Task") | D24: =SUMIFS(Backlog!$H:$H,Backlog!$D:$D,"E10",Backlog!$A:$A,"Task") | E24: =COUNTIFS(Backlog!$D:$D,"E10",Backlog!$A:$A,"Task",Backlog!$M:$M,"Done")
A25: E11 | B25: Steady State, Hypercare & Handover | C25: =COUNTIFS(Backlog!$D:$D,"E11",Backlog!$A:$A,"Task") | D25: =SUMIFS(Backlog!$H:$H,Backlog!$D:$D,"E11",Backlog!$A:$A,"Task") | E25: =COUNTIFS(Backlog!$D:$D,"E11",Backlog!$A:$A,"Task",Backlog!$M:$M,"Done")
A26: E12 | B26: Testing, UAT & Performance | C26: =COUNTIFS(Backlog!$D:$D,"E12",Backlog!$A:$A,"Task") | D26: =SUMIFS(Backlog!$H:$H,Backlog!$D:$D,"E12",Backlog!$A:$A,"Task") | E26: =COUNTIFS(Backlog!$D:$D,"E12",Backlog!$A:$A,"Task",Backlog!$M:$M,"Done")
A27: E13 | B27: Capacity & Resourcing | C27: =COUNTIFS(Backlog!$D:$D,"E13",Backlog!$A:$A,"Task") | D27: =SUMIFS(Backlog!$H:$H,Backlog!$D:$D,"E13",Backlog!$A:$A,"Task") | E27: =COUNTIFS(Backlog!$D:$D,"E13",Backlog!$A:$A,"Task",Backlog!$M:$M,"Done")
A28: E14 | B28: Model Implementation Documentation (IDG) | C28: =COUNTIFS(Backlog!$D:$D,"E14",Backlog!$A:$A,"Task") | D28: =SUMIFS(Backlog!$H:$H,Backlog!$D:$D,"E14",Backlog!$A:$A,"Task") | E28: =COUNTIFS(Backlog!$D:$D,"E14",Backlog!$A:$A,"Task",Backlog!$M:$M,"Done")
