Workbook

Sheet Master Task List
A1: ABSA x EXL Model Hosting — Master Task List
A3: Task ID | B3: Phase | C3: Category | D3: Task | E3: Owner | F3: RACI: R | G3: RACI: A | H3: Priority | I3: Effort (d) | J3: Start | K3: End | L3: Duration (d) | M3: Dependencies | N3: Status | O3: Delivery | P3: Risk | Q3: Notes
A4: T001 | B4: P1 | C4: Project Governance & Scope | D4: Confirm project kickoff agenda and stakeholder list | E4: BOTH | F4: BOTH | G4: Steering Committee | H4: Critical | I4: 2 | J4: 46023 | K4: 46026 | L4: =K4-J4+1 | N4: Not Started | O4: Planned | P4: Low | Q4: Kickoff meeting
A5: T002 | B5: P1 | C5: Project Governance & Scope | D5: SPOCs from ABSA and EXL | E5: BOTH | F5: BOTH | G5: Exec Sponsor | H5: Critical | I5: 1 | J5: 46026 | K5: 46029 | L5: =K5-J5+1 | M5: T001 | N5: Not Started | O5: Planned | P5: Low | Q5: Single Points of Contact each side
A6: T003 | B6: P1 | C6: Project Governance & Scope | D6: Finalize governance structure and working cadence | E6: BOTH | F6: BOTH | G6: Steering Committee | H6: Critical | I6: 3 | J6: 46029 | K6: 46032 | L6: =K6-J6+1 | M6: T002 | N6: Not Started | O6: Planned | P6: Low | Q6: Weekly standup + monthly steering
A7: T004 | B7: P1 | C7: Project Governance & Scope | D7: Review scope, exclusions, assumptions, dependencies | E7: BOTH | F7: BOTH | G7: Steering Committee | H7: High | I7: 3 | J7: 46032 | K7: 46035 | L7: =K7-J7+1 | M7: T003 | N7: Not Started | O7: Planned | P7: Medium | Q7: RACI + dependency log
A8: T005 | B8: P1 | C8: Project Governance & Scope | D8: Agree delivery plan for the initial 10 models | E8: BOTH | F8: BOTH | G8: ABSA Risk Owner | H8: Critical | I8: 5 | J8: 46035 | K8: 46038 | L8: =K8-J8+1 | M8: T004 | N8: Not Started | O8: Planned | P8: Medium | Q8: Sequencing: Group 1 (2) -> Group 2 (8)
A9: T006 | B9: P1 | C9: Project Governance & Scope | D9: Confirm run frequency for each of the initial models | E9: BOTH | F9: BOTH | G9: ABSA Risk Owner | H9: High | I9: 3 | J9: 46038 | K9: 46041 | L9: =K9-J9+1 | M9: T005 | N9: Not Started | O9: Planned | P9: Low | Q9: Daily / weekly / monthly cadence per model
A10: T007 | B10: P1 | C10: Project Governance & Scope | D10: Share approved model documents (initial set) | E10: ABSA | F10: ABSA | G10: ABSA Model Owner | H10: Critical | I10: 5 | J10: 46041 | K10: 46044 | L10: =K10-J10+1 | M10: T002 | N10: Not Started | O10: Blocked | P10: High | Q10: Model dev specs + validation reports
A11: T008 | B11: P1 | C11: Project Governance & Scope | D11: Share model code, supporting artefacts, benchmark outputs | E11: ABSA | F11: ABSA | G11: ABSA Model Owner | H11: Critical | I11: 5 | J11: 46044 | K11: 46047 | L11: =K11-J11+1 | M11: T007 | N11: Not Started | O11: Blocked | P11: High | Q11: Reference golden data for reconciliation
A12: T009 | B12: P1 | C12: Project Governance & Scope | D12: Agree PIR expectations and sign-off checkpoints | E12: BOTH | F12: BOTH | G12: ABSA Risk Owner | H12: Critical | I12: 3 | J12: 46047 | K12: 46050 | L12: =K12-J12+1 | M12: T004 | N12: Not Started | O12: Planned | P12: Medium | Q12: Post-Implementation Review framework
A13: T010 | B13: P1 | C13: Project Governance & Scope | D13: Create project logger | E13: EXL | F13: EXL | G13: Program Mgr | H13: Medium | I13: 2 | J13: 46050 | K13: 46053 | L13: =K13-J13+1 | M13: T003 | N13: Not Started | O13: Planned | P13: Low | Q13: Jira / Confluence / equivalent
A14: T011 | B14: P2 | C14: Architecture, Access & Connectivity | D14: Review target architecture + secure transfer approach | E14: BOTH | F14: BOTH | G14: Architecture Board | H14: Critical | I14: 5 | J14: 46037 | K14: 46040 | L14: =K14-J14+1 | M14: T001 | N14: In Progress | O14: Partial | P14: Medium | Q14: ADRs 0001-0010 capture decisions
A15: T012 | B15: P2 | C15: Architecture, Access & Connectivity | D15: Approve final architecture for implementation | E15: ABSA | F15: ABSA | G15: ABSA Architect | H15: Critical | I15: 3 | J15: 46040 | K15: 46043 | L15: =K15-J15+1 | M15: T011 | N15: Not Started | O15: Blocked | P15: High | Q15: Awaits ABSA sign-off
A16: T013 | B16: P2 | C16: Architecture, Access & Connectivity | D16: Complete ABSA internal cloud approvals | E16: ABSA | F16: ABSA | G16: ABSA Architect | H16: Critical | I16: 10 | J16: 46044 | K16: 46047 | L16: =K16-J16+1 | M16: T012 | N16: Not Started | O16: Blocked | P16: High | Q16: ABSA-side governance
... A68: T065 | B68: P8a | C68: Group 2: Remaining 8 Models | D68: Reconcile Group 2 outputs with benchmarks | E68: BOTH | F68: BOTH | G68: ABSA Model Owner | H68: Critical | I68: 10 | J68: 46163 | K68: 46173 | L68: =K68-J68+1 | M68: T064 | N68: Not Started | O68: Planned | P68: Medium | Q68: Same framework as Group 1
A69: T066 | B69: P8a | C69: Group 2: Remaining 8 Models | D69: Resolve defects during Group 2 testing | E69: BOTH | F69: BOTH | G69: ABSA Model Owner | H69: Critical | I69: 10 | J69: 46173 | K69: 46183 | L69: =K69-J69+1 | M69: T065 | N69: Not Started | O69: Planned | P69: Medium
A70: T067 | B70: P8a | C70: Group 2: Remaining 8 Models | D70: Complete PIR for Group 2 models | E70: BOTH | F70: BOTH | G70: ABSA Risk Owner | H70: Critical | I70: 8 | J70: 46183 | K70: 46193 | L70: =K70-J70+1 | M70: T066 | N70: Not Started | O70: Planned | P70: Medium
A71: T068 | B71: P8a | C71: Group 2: Remaining 8 Models | D71: MILESTONE: Obtain sign-off for Group 2 | E71: ABSA | F71: ABSA | G71: ABSA Risk Owner | H71: Critical | I71: 2 | J71: 46193 | K71: 46203 | L71: =K71-J71+1 | M71: T067 | N71: Not Started | O71: Planned | P71: Medium | Q71: Closes initial-onboarding scope
A72: T069 | B72: P8b | C72: Dashboards & Delivery | D72: Agree dashboard views, recipients, access levels | E72: BOTH | F72: BOTH | G72: ABSA Risk Owner | H72: High | I72: 3 | J72: 46143 | K72: 46151 | L72: =K72-J72+1 | M72: T048 | N72: Not Started | O72: Planned | P72: Low | Q72: Who sees what, when
A73: T070 | B73: P8b | C73: Dashboards & Delivery | D73: Build monitoring dashboard for runs + exceptions | E73: EXL | F73: EXL | G73: Tech Lead | H73: High | I73: 10 | J73: 46151 | K73: 46159 | L73: =K73-J73+1 | M73: T069 | N73: Not Started | O73: Planned | P73: Medium | Q73: CloudWatch + Grafana or equivalent
A74: T071 | B74: P8b | C74: Dashboards & Delivery | D74: Configure notifications + alert routing for failures | E74: BOTH | F74: BOTH | G74: Tech Lead | H74: High | I74: 3 | J74: 46160 | K74: 46168 | L74: =K74-J74+1 | M74: T070 | N74: Not Started | O74: Planned | P74: Medium | Q74: SNS / PagerDuty / Slack
A75: T072 | B75: P8b | C75: Dashboards & Delivery | D75: Validate dashboard for inputs, outputs, failures | E75: BOTH | F75: BOTH | G75: ABSA Risk Owner | H75: High | I75: 3 | J75: 46168 | K75: 46176 | L75: =K75-J75+1 | M75: T070 | N75: Not Started | O75: Planned | P75: Low
A76: T073 | B76: P8b | C76: Dashboards & Delivery | D76: Set up secure output delivery process to ABSA | E76: EXL | F76: EXL | G76: Compliance Lead | H76: Critical | I76: 5 | J76: 46177 | K76: 46185 | L76: =K76-J76+1 | M76: T018 | N76: In Progress | O76: Partial | P76: Medium | Q76: S3 replication path
A77: T074 | B77: P8b | C77: Dashboards & Delivery | D77: Confirm operational runbooks + support contacts | E77: BOTH | F77: BOTH | G77: Program Mgr | H77: High | I77: 3 | J77: 46185 | K77: 46193 | L77: =K77-J77+1 | M77: T070 | N77: In Progress | O77: Partial | P77: Medium | Q77: docs/runbooks/ started
A78: T075 | B78: P8b | C78: Dashboards & Delivery | D78: Publish runbooks + operating procedures + handover | E78: EXL | F78: EXL | G78: Program Mgr | H78: Critical | I78: 5 | J78: 46194 | K78: 46202 | L78: =K78-J78+1 | M78: T074 | N78: In Progress | O78: Partial | P78: Medium | Q78: Demo + key-rotation runbooks done
A79: T076 | B79: P9a | C79: Steady State Support | D79: Start scheduled production scoring | E79: EXL | F79: EXL | G79: Tech Lead | H79: Critical | I79: 5 | J79: 46204 | K79: 46225 | L79: =K79-J79+1 | M79: T068,T075 | N79: Not Started | O79: Planned | P79: Medium
A80: T077 | B80: P9a | C80: Steady State Support | D80: Monitor daily, weekly, monthly scoring runs | E80: EXL | F80: EXL | G80: Tech Lead | H80: High | I80: 0 | J80: 46225 | K80: 46246 | L80: =K80-J80+1 | M80: T076 | N80: Not Started | O80: Planned | P80: Low | Q80: Ongoing
A81: T078 | B81: P9a | C81: Steady State Support | D81: Track run failures + coordinate recovery actions | E81: BOTH | F81: BOTH | G81: ABSA Risk Owner | H81: Critical | I81: 0 | J81: 46246 | K81: 46267 | L81: =K81-J81+1 | M81: T076 | N81: Not Started | O81: Planned | P81: Medium | Q81: Incident response process
A82: T079 | B82: P9a | C82: Steady State Support | D82: Maintain audit trail for every scoring run and delivery | E82: EXL | F82: EXL | G82: Compliance Lead | H82: Critical | I82: 0 | J82: 46268 | K82: 46289 | L82: =K82-J82+1 | M82: T076 | N82: Done | O82: Done | P82: Low | Q82: registry-api audit + signed manifests
A83: T080 | B83: P9a | C83: Steady State Support | D83: Review data drift, anomalies, scoring exceptions | E83: BOTH | F83: BOTH | G83: ABSA Risk Owner | H83: High | I83: 0 | J83: 46289 | K83: 46310 | L83: =K83-J83+1 | M83: T076 | N83: Not Started | O83: Planned | P83: Medium | Q83: *** Need Comment: drift framework ***
A84: T081 | B84: P9a | C84: Steady State Support | D84: Manage approved changes | E84: BOTH | F84: BOTH | G84: ABSA Risk Owner | H84: High | I84: 0 | J84: 46311 | K84: 46332 | L84: =K84-J84+1 | M84: T076 | N84: Not Started | O84: Planned | P84: Medium | Q84: *** Need Comment: change-mgmt cadence ***
A85: T082 | B85: P9a | C85: Steady State Support | D85: Refresh access, whitelists, secrets when required | E85: BOTH | F85: BOTH | G85: Compliance Lead | H85: High | I85: 0 | J85: 46332 | K85: 46353 | L85: =K85-J85+1 | M85: T076 | N85: Not Started | O85: Planned | P85: Medium | Q85: *** Need Comment: rotation cadence ***
A86: T083 | B86: P9a | C86: Steady State Support | D86: Archive model data + outputs as per retention rules | E86: EXL | F86: EXL | G86: Compliance Lead | H86: Medium | I86: 0 | J86: 46353 | K86: 46374 | L86: =K86-J86+1 | M86: T076 | N86: Not Started | O86: Planned | P86: Low | Q86: S3 lifecycle policies
A87: T084 | B87: P9a | C87: Steady State Support | D87: Conduct periodic service review with ABSA | E87: BOTH | F87: BOTH | G87: ABSA Risk Owner | H87: High | I87: 0 | J87: 46375 | K87: 46396 | L87: =K87-J87+1 | M87: T076 | N87: Not Started | O87: Planned | P87: Low | Q87: Quarterly cadence
A88: T085 | B88: P9a | C88: Steady State Support | D88: Handle operational incidents + secondary support | E88: EXL | F88: EXL | G88: Program Mgr | H88: Critical | I88: 0 | J88: 46396 | K88: 46417 | L88: =K88-J88+1 | M88: T076 | N88: Not Started | O88: Planned | P88: Medium
A89: T086 | B89: P9b | C89: New Model Onboarding | D89: Review each new onboarding request + classify model type | E89: BOTH | F89: BOTH | G89: Program Mgr | H89: High | I89: 2 | J89: 46204 | K89: 46239 | L89: =K89-J89+1 | M89: T068 | N89: Not Started | O89: Planned | P89: Low | Q89: Standard-batch / Scalable-batch / Realtime
A90: T087 | B90: P9b | C90: New Model Onboarding | D90: Collect approved artefacts, inputs, benchmark outputs | E90: ABSA | F90: ABSA | G90: ABSA Model Owner | H90: High | I90: 5 | J90: 46239 | K90: 46274 | L90: =K90-J90+1 | M90: T086 | N90: Not Started | O90: Planned | P90: Medium | Q90: Same intake contract
A91: T088 | B91: P9b | C91: New Model Onboarding | D91: Reuse existing template for subsequent model of same type | E91: EXL | F91: EXL | G91: Tech Lead | H91: Medium | I91: 3 | J91: 46275 | K91: 46310 | L91: =K91-J91+1 | M91: T087 | N91: Done | O91: Done | P91: Low | Q91: pipeline-factory regenerates
A92: T089 | B92: P9b | C92: New Model Onboarding | D92: Build type-specific controls for new model category | E92: EXL | F92: EXL | G92: Tech Lead | H92: Medium | I92: 10 | J92: 46311 | K92: 46346 | L92: =K92-J92+1 | M92: T087 | N92: Not Started | O92: Planned | P92: Medium | Q92: If new tier introduced
...

Sheet Phase Summary
A1: Phase Summary
A3: Phase | B3: Months | C3: Title | D3: Task count (formula) | E3: Effort total (formula) | F3: Critical milestones | G3: Status snapshot
A4: P1 | B4: M1 | C4: Project Governance & Scope | D4: =COUNTIF('Master Task List'!B:B,"P1") | E4: =SUMIF('Master Task List'!B:B,"P1",'Master Task List'!I:I) | F4: SPOCs identified · scope sign-off | G4: =COUNTIFS('Master Task List'!B:B,"P1",'Master Task List'!O:O,"Done")&" Done · "&COUNTIFS('Master Task List'!B:B,"P1",'Master Task List'!O:O,"Partial")&" Partial · "&COUNTIFS('Master Task List'!B:B,"P1",'Master Task List'!O:O,"Planned")&" Planned · "&COUNTIFS('Master Task List'!B:B,"P1",'Master Task List'!O:O,"Blocked")&" Blocked"
A5: P2 | B5: M1-2 | C5: Architecture, Access & Connectivity | D5: =COUNTIF('Master Task List'!B:B,"P2") | E5: =SUMIF('Master Task List'!B:B,"P2",'Master Task List'!I:I) | F5: ABSA architecture sign-off · IAM trust established | G5: =COUNTIFS('Master Task List'!B:B,"P2",'Master Task List'!O:O,"Done")&" Done · "&COUNTIFS('Master Task List'!B:B,"P2",'Master Task List'!O:O,"Partial")&" Partial · "&COUNTIFS('Master Task List'!B:B,"P2",'Master Task List'!O:O,"Planned")&" Planned · "&COUNTIFS('Master Task List'!B:B,"P2",'Master Task List'!O:O,"Blocked")&" Blocked"
A6: P3 | B6: M1-2 | C6: Data & Code Readiness | D6: =COUNTIF('Master Task List'!B:B,"P3") | E6: =SUMIF('Master Task List'!B:B,"P3",'Master Task List'!I:I) | F6: First model code + data + benchmarks in intake pipeline | G6: =COUNTIFS('Master Task List'!B:B,"P3",'Master Task List'!O:O,"Done")&" Done · "&COUNTIFS('Master Task List'!B:B,"P3",'Master Task List'!O:O,"Partial")&" Partial · "&COUNTIFS('Master Task List'!B:B,"P3",'Master Task List'!O:O,"Planned")&" Planned · "&COUNTIFS('Master Task List'!B:B,"P3",'Master Task List'!O:O,"Blocked")&" Blocked"
A7: P4 | B7: M2-3 | C7: Platform Foundation Build | D7: =COUNTIF('Master Task List'!B:B,"P4") | E7: =SUMIF('Master Task List'!B:B,"P4",'Master Task List'!I:I) | F7: Real AWS accounts deployed via Terraform | G7: =COUNTIFS('Master Task List'!B:B,"P4",'Master Task List'!O:O,"Done")&" Done · "&COUNTIFS('Master Task List'!B:B,"P4",'Master Task List'!O:O,"Partial")&" Partial · "&COUNTIFS('Master Task List'!B:B,"P4",'Master Task List'!O:O,"Planned")&" Planned · "&COUNTIFS('Master Task List'!B:B,"P4",'Master Task List'!O:O,"Blocked")&" Blocked"
A8: P5 | B8: M2-6 | C8: Controls, Security & Change Mgmt | D8: =COUNTIF('Master Task List'!B:B,"P5") | E8: =SUMIF('Master Task List'!B:B,"P5",'Master Task List'!I:I) | F8: Cross-cutting; runs alongside Phases 4-8 | G8: =COUNTIFS('Master Task List'!B:B,"P5",'Master Task List'!O:O,"Done")&" Done · "&COUNTIFS('Master Task List'!B:B,"P5",'Master Task List'!O:O,"Partial")&" Partial · "&COUNTIFS('Master Task List'!B:B,"P5",'Master Task List'!O:O,"Planned")&" Planned · "&COUNTIFS('Master Task List'!B:B,"P5",'Master Task List'!O:O,"Blocked")&" Blocked"
A9: P6 | B9: M3-4 | C9: Code Optimization & Pipeline Setup | D9: =COUNTIF('Master Task List'!B:B,"P6") | E9: =SUMIF('Master Task List'!B:B,"P6",'Master Task List'!I:I) | F9: Pipeline template registered for first model | G9: =COUNTIFS('Master Task List'!B:B,"P6",'Master Task List'!O:O,"Done")&" Done · "&COUNTIFS('Master Task List'!B:B,"P6",'Master Task List'!O:O,"Partial")&" Partial · "&COUNTIFS('Master Task List'!B:B,"P6",'Master Task List'!O:O,"Planned")&" Planned · "&COUNTIFS('Master Task List'!B:B,"P6",'Master Task List'!O:O,"Blocked")&" Blocked"
A10: P7 | B10: M4 | C10: Group 1: First 2 Models | D10: =COUNTIF('Master Task List'!B:B,"P7") | E10: =SUMIF('Master Task List'!B:B,"P7",'Master Task List'!I:I) | F10: *** ABSA SIGN-OFF — BIGGEST MILESTONE *** | G10: =COUNTIFS('Master Task List'!B:B,"P7",'Master Task List'!O:O,"Done")&" Done · "&COUNTIFS('Master Task List'!B:B,"P7",'Master Task List'!O:O,"Partial")&" Partial · "&COUNTIFS('Master Task List'!B:B,"P7",'Master Task List'!O:O,"Planned")&" Planned · "&COUNTIFS('Master Task List'!B:B,"P7",'Master Task List'!O:O,"Blocked")&" Blocked"
A11: P8a | B11: M5-6 | C11: Group 2: Remaining 8 Models | D11: =COUNTIF('Master Task List'!B:B,"P8a") | E11: =SUMIF('Master Task List'!B:B,"P8a",'Master Task List'!I:I) | F11: All 10 models in production scoring | G11: =COUNTIFS('Master Task List'!B:B,"P8a",'Master Task List'!O:O,"Done")&" Done · "&COUNTIFS('Master Task List'!B:B,"P8a",'Master Task List'!O:O,"Partial")&" Partial · "&COUNTIFS('Master Task List'!B:B,"P8a",'Master Task List'!O:O,"Planned")&" Planned · "&COUNTIFS('Master Task List'!B:B,"P8a",'Master Task List'!O:O,"Blocked")&" Blocked"
A12: P8b | B12: M5-6 | C12: Dashboards & Delivery Readiness | D12: =COUNTIF('Master Task List'!B:B,"P8b") | E12: =SUMIF('Master Task List'!B:B,"P8b",'Master Task List'!I:I) | F12: Dashboards live; runbooks published | G12: =COUNTIFS('Master Task List'!B:B,"P8b",'Master Task List'!O:O,"Done")&" Done · "&COUNTIFS('Master Task List'!B:B,"P8b",'Master Task List'!O:O,"Partial")&" Partial · "&COUNTIFS('Master Task List'!B:B,"P8b",'Master Task List'!O:O,"Planned")&" Planned · "&COUNTIFS('Master Task List'!B:B,"P8b",'Master Task List'!O:O,"Blocked")&" Blocked"
A13: P9a | B13: M7+ | C13: Steady State Support | D13: =COUNTIF('Master Task List'!B:B,"P9a") | E13: =SUMIF('Master Task List'!B:B,"P9a",'Master Task List'!I:I) | F13: Quarterly reviews; ongoing ops | G13: =COUNTIFS('Master Task List'!B:B,"P9a",'Master Task List'!O:O,"Done")&" Done · "&COUNTIFS('Master Task List'!B:B,"P9a",'Master Task List'!O:O,"Partial")&" Partial · "&COUNTIFS('Master Task List'!B:B,"P9a",'Master Task List'!O:O,"Planned")&" Planned · "&COUNTIFS('Master Task List'!B:B,"P9a",'Master Task List'!O:O,"Blocked")&" Blocked"
A14: P9b | B14: M7+ | C14: New Model Onboarding | D14: =COUNTIF('Master Task List'!B:B,"P9b") | E14: =SUMIF('Master Task List'!B:B,"P9b",'Master Task List'!I:I) | F14: Template-driven new model ramp | G14: =COUNTIFS('Master Task List'!B:B,"P9b",'Master Task List'!O:O,"Done")&" Done · "&COUNTIFS('Master Task List'!B:B,"P9b",'Master Task List'!O:O,"Partial")&" Partial · "&COUNTIFS('Master Task List'!B:B,"P9b",'Master Task List'!O:O,"Planned")&" Planned · "&COUNTIFS('Master Task List'!B:B,"P9b",'Master Task List'!O:O,"Blocked")&" Blocked"
A15: M1 | B15: Jun W2 | C15: Jenkins Migration: Foundation | D15: =COUNTIF('Master Task List'!B:B,"M1") | E15: =SUMIF('Master Task List'!B:B,"M1",'Master Task List'!I:I) | F15: ADR-0011 accepted · sandbox proves library | G15: =COUNTIFS('Master Task List'!B:B,"M1",'Master Task List'!O:O,"Done")&" Done · "&COUNTIFS('Master Task List'!B:B,"M1",'Master Task List'!O:O,"Partial")&" Partial · "&COUNTIFS('Master Task List'!B:B,"M1",'Master Task List'!O:O,"Planned")&" Planned · "&COUNTIFS('Master Task List'!B:B,"M1",'Master Task List'!O:O,"Blocked")&" Blocked"
A16: M2 | B16: Jun W3-4 | C16: Jenkins Migration: AWS-touching | D16: =COUNTIF('Master Task List'!B:B,"M2") | E16: =SUMIF('Master Task List'!B:B,"M2",'Master Task List'!I:I) | F16: signing-foundation supports both providers · parallel run | G16: =COUNTIFS('Master Task List'!B:B,"M2",'Master Task List'!O:O,"Done")&" Done · "&COUNTIFS('Master Task List'!B:B,"M2",'Master Task List'!O:O,"Partial")&" Partial · "&COUNTIFS('Master Task List'!B:B,"M2",'Master Task List'!O:O,"Planned")&" Planned · "&COUNTIFS('Master Task List'!B:B,"M2",'Master Task List'!O:O,"Blocked")&" Blocked"
A17: M3 | B17: Jul W1 | C17: Jenkins Migration: Cutover | D17: =COUNTIF('Master Task List'!B:B,"M3") | E17: =SUMIF('Master Task List'!B:B,"M3",'Master Task List'!I:I) | F17: Branch protection flipped · GHA retired | G17: =COUNTIFS('Master Task List'!B:B,"M3",'Master Task List'!O:O,"Done")&" Done · "&COUNTIFS('Master Task List'!B:B,"M3",'Master Task List'!O:O,"Partial")&" Partial · "&COUNTIFS('Master Task List'!B:B,"M3",'Master Task List'!O:O,"Planned")&" Planned · "&COUNTIFS('Master Task List'!B:B,"M3",'Master Task List'!O:O,"Blocked")&" Blocked"

Sheet Milestones & Gates
A1: Milestones & Gates
A3: Milestone ID | B3: Description | C3: Target Date | D3: Owner | E3: Status | F3: Gate Criteria
A4: M01 | B4: Project kickoff complete + SPOCs identified | C4: 46037 | D4: Program Mgr | E4: Not Started | F4: Signed kickoff minutes; SPOC names on file
A5: M02 | B5: Scope + 10-model delivery plan signed off | C5: 46053 | D5: Steering Committee | E5: Not Started | F5: Scope doc approved; sequencing locked
A6: M03 | B6: Architecture sign-off from ABSA | C6: 46068 | D6: ABSA Architect | E6: Blocked | F6: Architecture review board minutes + decision log
A7: M04 | B7: EXL AWS landing zone live + IAM trust established | C7: 46081 | D7: EXL Cloud Eng | E7: Partial | F7: Real account IDs provisioned; cross-account roles verifiable
A8: M05 | B8: First ABSA package transferred + validated | C8: 46081 | D8: Tech Lead | E8: Blocked | F8: code-intake validate exits 0; manifest signed
A9: M06 | B9: Platform foundation built + security control sign-off | C9: 46112 | D9: Tech Lead | E9: Partial | F9: Control matrix evidence + readiness review
A10: M07 | B10: Code optimization complete + pipeline templates live | C10: 46127 | D10: Tech Lead | E10: Planned | F10: Pipeline template registered for first model type
A11: M08 | B11: *** GROUP 1 SIGN-OFF (2 MODELS) *** | C11: 46142 | D11: ABSA Risk Owner | E11: Blocked | F11: PIR complete; benchmark reconciliation passes
A12: M09 | B12: *** GROUP 2 SIGN-OFF (REMAINING 8 MODELS) *** | C12: 46203 | D12: ABSA Risk Owner | E12: Planned | F12: All 10 models reconciled; PIR sign-off
A13: M10 | B13: Dashboards + delivery handover published | C13: 46203 | D13: Program Mgr | E13: Planned | F13: Runbooks published; support contacts confirmed
A14: M11 | B14: Steady-state go-live | C14: 46204 | D14: Program Mgr | E14: Planned | F14: First quarterly review scheduled; ops contacts staffed
A15: M12 | B15: Jenkins identity model confirmed (IRSA vs instance) | C15: 46187 | D15: ABSA Cloud Platform | E15: Blocked | F15: *** Gates entire Sprint M2 of Jenkins migration ***
A16: M13 | B16: GHA retired; Jenkins is the sole CI gate | C16: 46208 | D16: EXL DevOps | E16: Planned | F16: Branch protection flipped; .disabled.yml retained 1 release

Sheet Risk Register
A1: Risk Register
A3: Risk ID | B3: Description | C3: Phase | D3: Probability (1-5) | E3: Impact (1-5) | F3: Score (P*I) | G3: Mitigation | H3: Owner
A4: R01 | B4: ABSA account onboarding (real AWS account IDs + IAM principals) delayed | C4: P2/P4 | D4: 4 | E4: 5 | F4: =D4*E4 | G4: Pre-stage Terraform + use LocalStack demo to keep CI green; escalate to Steering by end of Month 1 | H4: ABSA Architect
A5: R02 | B5: ABSA-side internal cloud approvals slip past Month 2 | C5: P2 | D5: 3 | E5: 5 | F5: =D5*E5 | G5: Start approval process before kickoff; weekly check-in with ABSA cloud team | H5: ABSA Architect
A6: R03 | B6: Group 1 sign-off (Month 4) slips, cascading into Group 2 and steady state | C6: P7 | D6: 3 | E6: 5 | F6: =D6*E6 | G6: Use Group 1 onboarding plan as dress rehearsal; pre-stage Group 2 templates | H6: ABSA Risk Owner
A7: R04 | B7: ML compute platform choice (SFN+Lambda vs SageMaker) blocks Phase 4 build | C7: P4 | D7: 3 | E7: 4 | F7: =D7*E7 | G7: Decision required by end of Month 2; architecture review board agenda item | H7: Tech Lead
A8: R05 | B8: Benchmark reconciliation discrepancies require model code rewrite | C8: P6/P7 | D8: 3 | E8: 4 | F8: =D8*E8 | G8: Validate scoring logic incrementally during code optimization; record per-feature deltas | H8: EXL ML Eng
A9: R06 | B9: Cross-account encrypted transfer path not validated end-to-end before Phase 4 | C9: P2 | D9: 2 | E9: 4 | F9: =D9*E9 | G9: Phase-gate Phase 4 on Phase 2 transfer validation; LocalStack demo verifies the shape today | H9: EXL Cloud Eng
A10: R07 | B10: SSO federation testing reveals incompatible identity provider config | C10: P2 | D10: 2 | E10: 3 | F10: =D10*E10 | G10: Joint test in Month 2; fall back to direct IAM if SSO blocks | H10: EXL Cloud Eng
A11: R08 | B11: Data quality issues (drift, schema mismatch) in initial intake delay code optimization | C11: P3/P6 | D11: 3 | E11: 4 | F11: =D11*E11 | G11: Run code-intake validate on first arrival; reject + return to ABSA immediately | H11: EXL Eng
A12: R09 | B12: PIR review reveals input variable misalignment, requires re-scope | C12: P7 | D12: 2 | E12: 5 | F12: =D12*E12 | G12: Lock input variables in Phase 1; PIR rehearsal during Group 1 | H12: ABSA Risk Owner
A13: R10 | B13: Production scoring SLA cannot be met on selected ML compute platform | C13: P9a | D13: 2 | E13: 4 | F13: =D13*E13 | G13: Load-test in Phase 7 before Group 1 go-live | H13: EXL ML Eng
A14: R11 | B14: KMS signing key compromise during operations | C14: P9a | D14: 1 | E14: 5 | F14: =D14*E14 | G14: Rotation runbook (docs/runbooks/kms-key-rotation.md) in place; quarterly drill | H14: Compliance Lead
A15: R12 | B15: Change management workflow not finalized before first production change | C15: P5 | D15: 2 | E15: 4 | F15: =D15*E15 | G15: Use registry-api approval state machine as baseline; document workflow by Month 3 | H15: Compliance Lead
... A18: R15 | B18: Signature byte-equivalence fails between GHA and Jenkins runs (canonical_json sensitivity to env) | C18: M2 | D18: 2 | E18: 5 | F18: =D18*E18 | G18: Parallel-run week explicitly compares manifest digests; canonical_json is deterministic by spec but Python version drift could shift behaviour | H18: Tech Lead

Sheet Open Decisions
A1: Open Decisions
A3: Decision ID | B3: Description | C3: Phase Impact | D3: Owner | E3: Due Date | F3: Impact if not decided
A4: D01 | B4: Data drift detection framework: which metrics (PSI / KL-divergence / feature-distribution shift)? What window? Manual review vs automated alerting? | C4: P9a | D4: ABSA Risk Owner + EXL ML Eng | E4: 46173 | F4: Cannot ship dashboards (Phase 8b) without agreed drift metrics. Steady state ops lacks anomaly framework.
A5: D02 | B5: Change management cadence: production-change approval — registry's approve/retire state machine or separate Jira workflow? | C5: P5/P9a | D5: Compliance Lead + ABSA Risk Owner | E5: 46112 | F5: Group 1 production releases blocked without an agreed change workflow.
A6: D03 | B6: Access / secret rotation cadence (IAM principals, registrar tokens, dashboard access). KMS signing key has a runbook; the rest don't. | C6: P5/P9a | D6: Compliance Lead | E6: 46142 | F6: Audit findings if rotation cadence not documented before steady state.
A7: D04 | B7: ML compute platform: Step Functions + Lambda OR SageMaker Pipelines? | C7: P4 | D7: Tech Lead + Architecture Board | E7: 46081 | F7: Blocks Phase 4 ML compute setup. Affects pipeline-factory ASL renderer scope.
A8: D05 | B8: Real-time scoring tier SLA: what's the response budget? Lambda+APIGW / ECS Fargate / SageMaker endpoint? | C8: P4 | D8: Tech Lead + ABSA Architect | E8: 46112 | F8: Realtime ASL template is currently a placeholder. SLA drives the implementation choice.
A9: D06 | B9: Data-movement choice: S3 cross-account replication or SFTP transfer for scoring inputs/outputs? | C9: P2 | D9: ABSA Architect + EXL Cloud Eng | E9: 46068 | F9: Blocks Phase 2 secure transfer build. Both directions need this lock.
A10: D07 | B10: Multi-region: is the platform single-region (eu-west-1) or multi-region from day 1? | C10: P4 | D10: ABSA Architect | E10: 46096 | F10: Affects KMS replica strategy, signing-foundation scope, runbook structure.
A11: D08 | B11: Dashboard hosting: Grafana / CloudWatch native / QuickSight / something ABSA-supplied? | C11: P8b | D11: Program Mgr + ABSA Risk Owner | E11: 46142 | F11: Dashboard build (Phase 8b) blocked without tool decision.
A12: D09 | B12: Output delivery format to ABSA: signed S3 bucket / SFTP push / API pull? | C12: P8b | D12: ABSA Architect + EXL Cloud Eng | E12: 46142 | F12: Cannot finalize delivery runbook.

Sheet Dashboard
A1: Program Dashboard
A3: Tasks by Delivery Status | D3: Tasks by Owner
A4: Owner | B4: Count | D4: Owner | E4: Count
A5: Done | B5: =COUNTIF('Master Task List'!O:O,"Done") | D5: BOTH | E5: =COUNTIF('Master Task List'!E:E,"BOTH")
A6: Partial | B6: =COUNTIF('Master Task List'!O:O,"Partial") | D6: EXL | E6: =COUNTIF('Master Task List'!E:E,"EXL")
A7: Planned | B7: =COUNTIF('Master Task List'!O:O,"Planned") | D7: ABSA | E7: =COUNTIF('Master Task List'!E:E,"ABSA")
A8: Blocked | B8: =COUNTIF('Master Task List'!O:O,"Blocked") | D8: EXL (ABSA Side) | E8: =COUNTIF('Master Task List'!E:E,"EXL (ABSA Side)")
A9: In Progress | B9: =COUNTIF('Master Task List'!O:O,"In Progress")
A10: Not Started | B10: =COUNTIF('Master Task List'!O:O,"Not Started")
A11: Total | B11: =SUM(B5:B10)
A14: Tasks by Phase
A15: Phase | B15: Title | C15: Tasks | D15: Effort (d) | E15: Blocked | F15: Done
A16: P1 | B16: Governance | C16: =COUNTIF('Master Task List'!B:B,"P1") | D16: =SUMIF('Master Task List'!B:B,"P1",'Master Task List'!I:I) | E16: =COUNTIFS('Master Task List'!B:B,"P1",'Master Task List'!O:O,"Blocked") | F16: =COUNTIFS('Master Task List'!B:B,"P1",'Master Task List'!O:O,"Done")
A17: P2 | B17: Architecture | C17: =COUNTIF('Master Task List'!B:B,"P2") | D17: =SUMIF('Master Task List'!B:B,"P2",'Master Task List'!I:I) | E17: =COUNTIFS('Master Task List'!B:B,"P2",'Master Task List'!O:O,"Blocked") | F17: =COUNTIFS('Master Task List'!B:B,"P2",'Master Task List'!O:O,"Done")
A18: P3 | B18: Data/Code Readiness | C18: =COUNTIF('Master Task List'!B:B,"P3") | D18: =SUMIF('Master Task List'!B:B,"P3",'Master Task List'!I:I) | E18: =COUNTIFS('Master Task List'!B:B,"P3",'Master Task List'!O:O,"Blocked") | F18: =COUNTIFS('Master Task List'!B:B,"P3",'Master Task List'!O:O,"Done")
A19: P4 | B19: Platform Foundation | C19: =COUNTIF('Master Task List'!B:B,"P4") | D19: =SUMIF('Master Task List'!B:B,"P4",'Master Task List'!I:I) | E19: =COUNTIFS('Master Task List'!B:B,"P4",'Master Task List'!O:O,"Blocked") | F19: =COUNTIFS('Master Task List'!B:B,"P4",'Master Task List'!O:O,"Done")
A20: P5 | B20: Controls | C20: =COUNTIF('Master Task List'!B:B,"P5") | D20: =SUMIF('Master Task List'!B:B,"P5",'Master Task List'!I:I) | E20: =COUNTIFS('Master Task List'!B:B,"P5",'Master Task List'!O:O,"Blocked") | F20: =COUNTIFS('Master Task List'!B:B,"P5",'Master Task List'!O:O,"Done")
A21: P6 | B21: Code Optimization | C21: =COUNTIF('Master Task List'!B:B,"P6") | D21: =SUMIF('Master Task List'!B:B,"P6",'Master Task List'!I:I) | E21: =COUNTIFS('Master Task List'!B:B,"P6",'Master Task List'!O:O,"Blocked") | F21: =COUNTIFS('Master Task List'!B:B,"P6",'Master Task List'!O:O,"Done")
A22: P7 | B22: Group 1 (2 models) | C22: =COUNTIF('Master Task List'!B:B,"P7") | D22: =SUMIF('Master Task List'!B:B,"P7",'Master Task List'!I:I) | E22: =COUNTIFS('Master Task List'!B:B,"P7",'Master Task List'!O:O,"Blocked") | F22: =COUNTIFS('Master Task List'!B:B,"P7",'Master Task List'!O:O,"Done")
A23: P8a | B23: Group 2 (8 models) | C23: =COUNTIF('Master Task List'!B:B,"P8a") | D23: =SUMIF('Master Task List'!B:B,"P8a",'Master Task List'!I:I) | E23: =COUNTIFS('Master Task List'!B:B,"P8a",'Master Task List'!O:O,"Blocked") | F23: =COUNTIFS('Master Task List'!B:B,"P8a",'Master Task List'!O:O,"Done")
A24: P8b | B24: Dashboards | C24: =COUNTIF('Master Task List'!B:B,"P8b") | D24: =SUMIF('Master Task List'!B:B,"P8b",'Master Task List'!I:I) | E24: =COUNTIFS('Master Task List'!B:B,"P8b",'Master Task List'!O:O,"Blocked") | F24: =COUNTIFS('Master Task List'!B:B,"P8b",'Master Task List'!O:O,"Done")
A25: P9a | B25: Steady State | C25: =COUNTIF('Master Task List'!B:B,"P9a") | D25: =SUMIF('Master Task List'!B:B,"P9a",'Master Task List'!I:I) | E25: =COUNTIFS('Master Task List'!B:B,"P9a",'Master Task List'!O:O,"Blocked") | F25: =COUNTIFS('Master Task List'!B:B,"P9a",'Master Task List'!O:O,"Done")
A26: P9b | B26: New Model Onboarding | C26: =COUNTIF('Master Task List'!B:B,"P9b") | D26: =SUMIF('Master Task List'!B:B,"P9b",'Master Task List'!I:I) | E26: =COUNTIFS('Master Task List'!B:B,"P9b",'Master Task List'!O:O,"Blocked") | F26: =COUNTIFS('Master Task List'!B:B,"P9b",'Master Task List'!O:O,"Done")
A27: M1 | B27: Jenkins: Foundation | C27: =COUNTIF('Master Task List'!B:B,"M1") | D27: =SUMIF('Master Task List'!B:B,"M1",'Master Task List'!I:I) | E27: =COUNTIFS('Master Task List'!B:B,"M1",'Master Task List'!O:O,"Blocked") | F27: =COUNTIFS('Master Task List'!B:B,"M1",'Master Task List'!O:O,"Done")
A28: M2 | B28: Jenkins: AWS-touching | C28: =COUNTIF('Master Task List'!B:B,"M2") | D28: =SUMIF('Master Task List'!B:B,"M2",'Master Task List'!I:I) | E28: =COUNTIFS('Master Task List'!B:B,"M2",'Master Task List'!O:O,"Blocked") | F28: =COUNTIFS('Master Task List'!B:B,"M2",'Master Task List'!O:O,"Done")
A29: M3 | B29: Jenkins: Cutover | C29: =COUNTIF('Master Task List'!B:B,"M3") | D29: =SUMIF('Master Task List'!B:B,"M3",'Master Task List'!I:I) | E29: =COUNTIFS('Master Task List'!B:B,"M3",'Master Task List'!O:O,"Blocked") | F29: =COUNTIFS('Master Task List'!B:B,"M3",'Master Task List'!O:O,"Done")
